Workbook

Sheet About
A1: SoEDtICoS Share of Electricity Demand that Is Cost of Service
A2: Scope: state of PA | Data year: 2024
A4: Source: | B4: Retail electricity sales by serving entity (utility / marketer / CCA)
B5: U.S. Energy Information Administration (EIA)
B6: Form EIA-861 detailed data, Sales_Ult_Cust_2024.xlsx (sheet 'States')
B7: 2024
B8: https://www.eia.gov/electricity/data/eia861/
B9: Cost-of-service share = cost-of-service MWh / (cost-of-service + procurement) MWh for this jurisdiction. Ties to EIA published retail sales (Bundled+Energy).
A11: Notes:
A12: Classification | B12: LSE-based: cost-of-service = bundled sales of munis, cooperatives, federal/state/political-subdivision utilities, plus IOUs in non-restructured states (and the TX override utilities). Procurement = marketers, CCAs, any 'Energy' service-type sales, and IOUs in restructured states.
A13: Double-count fix | B13: Only Service Type Bundled or Energy enter the totals; 'Delivery' rows (the wires half of choice load) are classified 'excluded'.
A14: Exclusions | B14: EIA 'Adjustment' rows and 'Behind the Meter' ownership are excluded.
A15: Time profile | B15: Held FLAT 2021-2050 at the latest-year cost-of-service share. The analysis measures a single recent year; no independent forward projection is made.
A16: Restructured + overrides | B16: Editable on the Parameters tab. Non-ERCOT TX IOUs (util #s 55937/17718/17698/5701) are held cost-of-service.
A17: How it computes | B17: Source tab 'bucket' column classifies each row (reads Parameters via COUNTIF); the Share tab sums via SUMIFS; the SoEDtICoS tab = ROUND(share,3) flat across years. Edit Parameters and the EPS value recomputes.
A18: Caveat | B18: Staff-review input; verify against EIA primary sources. Restructured list and TX overrides are adjustable assumptions.

Sheet Parameters
A1: Parameters (editable — outputs recompute)
A3: Fully Restructured States | B3: Override Utility # | C3: Override Utility Name (reference)
A4: CT | B4: 55937 | C4: Entergy Texas Inc.
A5: DC | B5: 17718 | C5: Southwestern Public Service Co
A6: DE | B6: 17698 | C6: Southwestern Electric Power Co
A7: IL | B7: 5701 | C7: El Paso Electric Co
A8: MA
A9: MD
A10: ME
A11: NH
A12: NJ
A13: NY
A14: OH
A15: PA
A16: RI
A17: TX

Sheet EIA-861 Sales 2024
A1: Utility Characteristics | J1: RESIDENTIAL | M1: COMMERCIAL | P1: INDUSTRIAL | S1: TRANSPORTATION | V1: TOTAL
J2: Revenues | K2: Sales | L2: Customers | M2: Revenues | N2: Sales | O2: Customers | P2: Revenues | Q2: Sales | R2: Customers | S2: Revenues | T2: Sales | U2: Customers | V2: Revenues | W2: Sales | X2: Customers
A3: Data Year | B3: Utility Number | C3: Utility Name | D3: Part | E3: Service Type | F3: Data Type O = Observed I = Imputed | G3: State | H3: Ownership | I3: BA Code | J3: Thousand Dollars | K3: Megawatthours | L3: Count | M3: Thousand Dollars | N3: Megawatthours | O3: Count | P3: Thousand Dollars | Q3: Megawatthours | R3: Count | S3: Thousand Dollars | T3: Megawatthours | U3: Count | V3: Thousand Dollars | W3: Megawatthours | X3: Count | Y3: sales_mwh (derived) | Z3: bucket (derived)
A4: 2024 | B4: 113 | C4: Agway Energy Services, LLC | D4: B | E4: Energy | F4: O | G4: PA | H4: Retail Power Marketer | I4: PJM | J4: 972.7 | K4: 8449 | L4: 945 | M4: 95.2 | N4: 918 | O4: 46 | P4: 0 | Q4: 0 | R4: 0 | S4: 0 | T4: 0 | U4: 0 | V4: 1067.9 | W4: 9367 | X4: 991 | Y4: =IF(ISNUMBER($W4),$W4,0) | Z4: =IF(ISNUMBER(SEARCH("Adjustment",$C4)),"excluded",IF($H4="Behind the Meter","excluded",IF(NOT(OR($E4="Bundled",$E4="Energy")),"excluded",IF(OR($H4="Retail Power Marketer",$H4="Community Choice Aggregator",$E4="Energy"),"procurement",IF(OR($H4="Municipal",$H4="Cooperative",$H4="Federal",$H4="State",$H4="Political Subdivision"),"cost_service",IF($H4="Investor Owned",IF(AND(COUNTIF(Parameters!$A$4:$A$33,$G4)>0,COUNTIF(Parameters!$B$4:$B$33,$B4)=0),"procurement","cost_service"),"unclassified"))))))
A5: 2024 | B5: 1611 | C5: Messer Energy Services, Inc. | D5: B | E5: Energy | F5: O | G5: PA | H5: Retail Power Marketer | I5: PJM | J5: 0 | K5: 0 | L5: 0 | M5: 0 | N5: 0 | O5: 0 | P5: 29609 | Q5: 561049 | R5: 3 | S5: 0 | T5: 0 | U5: 0 | V5: 29609 | W5: 561049 | X5: 3 | Y5: =IF(ISNUMBER($W5),$W5,0) | Z5: =IF(ISNUMBER(SEARCH("Adjustment",$C5)),"excluded",IF($H5="Behind the Meter","excluded",IF(NOT(OR($E5="Bundled",$E5="Energy")),"excluded",IF(OR($H5="Retail Power Marketer",$H5="Community Choice Aggregator",$E5="Energy"),"procurement",IF(OR($H5="Municipal",$H5="Cooperative",$H5="Federal",$H5="State",$H5="Political Subdivision"),"cost_service",IF($H5="Investor Owned",IF(AND(COUNTIF(Parameters!$A$4:$A$33,$G5)>0,COUNTIF(Parameters!$B$4:$B$33,$B5)=0),"procurement","cost_service"),"unclassified"))))))
A6: 2024 | B6: 3329 | C6: Borough of Chambersburg | D6: A | E6: Bundled | F6: O | G6: PA | H6: Municipal | I6: PJM | J6: 11653.3 | K6: 97501 | L6: 9914 | M6: 12992.2 | N6: 119572 | O6: 1783 | P6: 9324.8 | Q6: 107070 | R6: 21 | S6: 0 | T6: 0 | U6: 0 | V6: 33970.3 | W6: 324143 | X6: 11718 | Y6: =IF(ISNUMBER($W6),$W6,0) | Z6: =IF(ISNUMBER(SEARCH("Adjustment",$C6)),"excluded",IF($H6="Behind the Meter","excluded",IF(NOT(OR($E6="Bundled",$E6="Energy")),"excluded",IF(OR($H6="Retail Power Marketer",$H6="Community Choice Aggregator",$E6="Energy"),"procurement",IF(OR($H6="Municipal",$H6="Cooperative",$H6="Federal",$H6="State",$H6="Political Subdivision"),"cost_service",IF($H6="Investor Owned",IF(AND(COUNTIF(Parameters!$A$4:$A$33,$G6)>0,COUNTIF(Parameters!$B$4:$B$33,$B6)=0),"procurement","cost_service"),"unclassified"))))))
A7: 2024 | B7: 3597 | C7: Citizens Electric Co - (PA) | D7: A | E7: Bundled | F7: O | G7: PA | H7: Investor Owned | I7: PJM | J7: 11121 | K7: 81599 | L7: 5958 | M7: 3124 | N7: 22397 | O7: 1128 | P7: 1182 | Q7: 9598 | R7: 22 | S7: 0 | T7: 0 | U7: 0 | V7: 15427 | W7: 113594 | X7: 7108 | Y7: =IF(ISNUMBER($W7),$W7,0) | Z7: =IF(ISNUMBER(SEARCH("Adjustment",$C7)),"excluded",IF($H7="Behind the Meter","excluded",IF(NOT(OR($E7="Bundled",$E7="Energy")),"excluded",IF(OR($H7="Retail Power Marketer",$H7="Community Choice Aggregator",$E7="Energy"),"procurement",IF(OR($H7="Municipal",$H7="Cooperative",$H7="Federal",$H7="State",$H7="Political Subdivision"),"cost_service",IF($H7="Investor Owned",IF(AND(COUNTIF(Parameters!$A$4:$A$33,$G7)>0,COUNTIF(Parameters!$B$4:$B$33,$B7)=0),"procurement","cost_service"),"unclassified"))))))
A8: 2024 | B8: 3597 | C8: Citizens Electric Co - (PA) | D8: C | E8: Delivery | F8: O | G8: PA | H8: Investor Owned | I8: PJM | J8: 5 | K8: 124 | L8: 5 | M8: 107 | N8: 3492 | O8: 43 | P8: 532 | Q8: 33691 | R8: 18 | S8: 0 | T8: 0 | U8: 0 | V8: 644 | W8: 37307 | X8: 66 | Y8: =IF(ISNUMBER($W8),$W8,0) | Z8: =IF(ISNUMBER(SEARCH("Adjustment",$C8)),"excluded",IF($H8="Behind the Meter","excluded",IF(NOT(OR($E8="Bundled",$E8="Energy")),"excluded",IF(OR($H8="Retail Power Marketer",$H8="Community Choice Aggregator",$E8="Energy"),"procurement",IF(OR($H8="Municipal",$H8="Cooperative",$H8="Federal",$H8="State",$H8="Political Subdivision"),"cost_service",IF($H8="Investor Owned",IF(AND(COUNTIF(Parameters!$A$4:$A$33,$G8)>0,COUNTIF(Parameters!$B$4:$B$33,$B8)=0),"procurement","cost_service"),"unclassified"))))))
A9: 2024 | B9: 4100 | C9: Just Energy Solutions Inc. | D9: B | E9: Energy | F9: O | G9: PA | H9: Retail Power Marketer | I9: PJM | J9: 5590.5 | K9: 47987 | L9: 5454 | M9: 1919.2 | N9: 11602 | O9: 1625 | P9: 0 | Q9: 0 | R9: 0 | S9: 0 | T9: 0 | U9: 0 | V9: 7509.7 | W9: 59589 | X9: 7079 | Y9: =IF(ISNUMBER($W9),$W9,0) | Z9: =IF(ISNUMBER(SEARCH("Adjustment",$C9)),"excluded",IF($H9="Behind the Meter","excluded",IF(NOT(OR($E9="Bundled",$E9="Energy")),"excluded",IF(OR($H9="Retail Power Marketer",$H9="Community Choice Aggregator",$E9="Energy"),"procurement",IF(OR($H9="Municipal",$H9="Cooperative",$H9="Federal",$H9="State",$H9="Political Subdivision"),"cost_service",IF($H9="Investor Owned",IF(AND(COUNTIF(Parameters!$A$4:$A$33,$G9)>0,COUNTIF(Parameters!$B$4:$B$33,$B9)=0),"procurement","cost_service"),"unclassified"))))))
A10: 2024 | B10: 5487 | C10: Duquesne Light Co | D10: A | E10: Bundled | F10: O | G10: PA | H10: Investor Owned | I10: PJM | J10: 685304 | K10: 3151995 | L10: 434171 | M10: 159148 | N10: 999403 | O10: 38515 | P10: 8532 | Q10: 63936 | R10: 332 | S10: . | T10: . | U10: . | V10: 852984 | W10: 4215334 | X10: 473018 | Y10: =IF(ISNUMBER($W10),$W10,0) | Z10: =IF(ISNUMBER(SEARCH("Adjustment",$C10)),"excluded",IF($H10="Behind the Meter","excluded",IF(NOT(OR($E10="Bundled",$E10="Energy")),"excluded",IF(OR($H10="Retail Power Marketer",$H10="Community Choice Aggregator",$E10="Energy"),"procurement",IF(OR($H10="Municipal",$H10="Cooperative",$H10="Federal",$H10="State",$H10="Political Subdivision"),"cost_service",IF($H10="Investor Owned",IF(AND(COUNTIF(Parameters!$A$4:$A$33,$G10)>0,COUNTIF(Parameters!$B$4:$B$33,$B10)=0),"procurement","cost_service"),"unclassified"))))))
A11: 2024 | B11: 5487 | C11: Duquesne Light Co | D11: C | E11: Delivery | F11: O | G11: PA | H11: Investor Owned | I11: PJM | J11: 99094 | K11: 877741 | L11: 116234 | M11: 165180 | N11: 4708846 | O11: 23855 | P11: 38301 | Q11: 2945306 | R11: 680 | S11: 1328 | T11: 14216 | U11: 1 | V11: 303903 | W11: 8546109 | X11: 140770 | Y11: =IF(ISNUMBER($W11),$W11,0) | Z11: =IF(ISNUMBER(SEARCH("Adjustment",$C11)),"excluded",IF($H11="Behind the Meter","excluded",IF(NOT(OR($E11="Bundled",$E11="Energy")),"excluded",IF(OR($H11="Retail Power Marketer",$H11="Community Choice Aggregator",$E11="Energy"),"procurement",IF(OR($H11="Municipal",$H11="Cooperative",$H11="Federal",$H11="State",$H11="Political Subdivision"),"cost_service",IF($H11="Investor Owned",IF(AND(COUNTIF(Parameters!$A$4:$A$33,$G11)>0,COUNTIF(Parameters!$B$4:$B$33,$B11)=0),"procurement","cost_service"),"unclassified"))))))
A12: 2024 | B12: 5880 | C12: Energy Coop of New York, Inc | D12: B | E12: Energy | F12: O | G12: PA | H12: Retail Power Marketer | I12: PJM | J12: 179 | K12: 1802 | L12: 156 | M12: 678 | N12: 9633 | O12: 158 | P12: 0 | Q12: 0 | R12: 0 | S12: 0 | T12: 0 | U12: 0 | V12: 857 | W12: 11435 | X12: 314 | Y12: =IF(ISNUMBER($W12),$W12,0) | Z12: =IF(ISNUMBER(SEARCH("Adjustment",$C12)),"excluded",IF($H12="Behind the Meter","excluded",IF(NOT(OR($E12="Bundled",$E12="Energy")),"excluded",IF(OR($H12="Retail Power Marketer",$H12="Community Choice Aggregator",$E12="Energy"),"procurement",IF(OR($H12="Municipal",$H12="Cooperative",$H12="Federal",$H12="State",$H12="Political Subdivision"),"cost_service",IF($H12="Investor Owned",IF(AND(COUNTIF(Parameters!$A$4:$A$33,$G12)>0,COUNTIF(Parameters!$B$4:$B$33,$B12)=0),"procurement","cost_service"),"unclassified"))))))
A13: 2024 | B13: 6458 | C13: Energy Harbor Corp. | D13: B | E13: Energy | F13: O | G13: PA | H13: Retail Power Marketer | I13: PJM | J13: 134640.8 | K13: 1245709 | L13: 105658 | M13: 58831.6 | N13: 893102 | O13: 3436 | P13: 134045.8 | Q13: 2707802 | R13: 127 | S13: 0 | T13: 0 | U13: 0 | V13: 327518.2 | W13: 4846613 | X13: 109221 | Y13: =IF(ISNUMBER($W13),$W13,0) | Z13: =IF(ISNUMBER(SEARCH("Adjustment",$C13)),"excluded",IF($H13="Behind the Meter","excluded",IF(NOT(OR($E13="Bundled",$E13="Energy")),"excluded",IF(OR($H13="Retail Power Marketer",$H13="Community Choice Aggregator",$E13="Energy"),"procurement",IF(OR($H13="Municipal",$H13="Cooperative",$H13="Federal",$H13="State",$H13="Political Subdivision"),"cost_service",IF($H13="Investor Owned",IF(AND(COUNTIF(Parameters!$A$4:$A$33,$G13)>0,COUNTIF(Parameters!$B$4:$B$33,$B13)=0),"procurement","cost_service"),"unclassified"))))))
A14: 2024 | B14: 7279 | C14: NextEra Energy Services, LLC | D14: B | E14: Energy | F14: O | G14: PA | H14: Retail Power Marketer | I14: PJM | J14: 17509.8 | K14: 124848 | L14: 11544 | M14: 88245.1 | N14: 1291326 | O14: 520 | P14: . | Q14: . | R14: . | S14: . | T14: . | U14: . | V14: 105754.9 | W14: 1416174 | X14: 12064 | Y14: =IF(ISNUMBER($W14),$W14,0) | Z14: =IF(ISNUMBER(SEARCH("Adjustment",$C14)),"excluded",IF($H14="Behind the Meter","excluded",IF(NOT(OR($E14="Bundled",$E14="Energy")),"excluded",IF(OR($H14="Retail Power Marketer",$H14="Community Choice Aggregator",$E14="Energy"),"procurement",IF(OR($H14="Municipal",$H14="Cooperative",$H14="Federal",$H14="State",$H14="Political Subdivision"),"cost_service",IF($H14="Investor Owned",IF(AND(COUNTIF(Parameters!$A$4:$A$33,$G14)>0,COUNTIF(Parameters!$B$4:$B$33,$B14)=0),"procurement","cost_service"),"unclassified"))))))
A15: 2024 | B15: 7554 | C15: Green Mountain Energy Company | D15: B | E15: Energy | F15: O | G15: PA | H15: Retail Power Marketer | I15: PJM | J15: 37241 | K15: 285360 | L15: 30875 | M15: 919 | N15: 11080 | O15: 13 | P15: 0 | Q15: 0 | R15: 0 | S15: 0 | T15: 0 | U15: 0 | V15: 38160 | W15: 296440 | X15: 30888 | Y15: =IF(ISNUMBER($W15),$W15,0) | Z15: =IF(ISNUMBER(SEARCH("Adjustment",$C15)),"excluded",IF($H15="Behind the Meter","excluded",IF(NOT(OR($E15="Bundled",$E15="Energy")),"excluded",IF(OR($H15="Retail Power Marketer",$H15="Community Choice Aggregator",$E15="Energy"),"procurement",IF(OR($H15="Municipal",$H15="Cooperative",$H15="Federal",$H15="State",$H15="Political Subdivision"),"cost_service",IF($H15="Investor Owned",IF(AND(COUNTIF(Parameters!$A$4:$A$33,$G15)>0,COUNTIF(Parameters!$B$4:$B$33,$B15)=0),"procurement","cost_service"),"unclassified"))))))
A16: 2024 | B16: 9949 | C16: Just Energy | D16: B | E16: Energy | F16: O | G16: PA | H16: Retail Power Marketer | I16: PJM | J16: 29825.8 | K16: 236938 | L16: 20938 | M16: 5.1 | N16: 45 | O16: 3 | P16: 0 | Q16: 0 | R16: 0 | S16: 0 | T16: 0 | U16: 0 | V16: 29830.9 | W16: 236983 | X16: 20941 | Y16: =IF(ISNUMBER($W16),$W16,0) | Z16: =IF(ISNUMBER(SEARCH("Adjustment",$C16)),"excluded",IF($H16="Behind the Meter","excluded",IF(NOT(OR($E16="Bundled",$E16="Energy")),"excluded",IF(OR($H16="Retail Power Marketer",$H16="Community Choice Aggregator",$E16="Energy"),"procurement",IF(OR($H16="Municipal",$H16="Cooperative",$H16="Federal",$H16="State",$H16="Political Subdivision"),"cost_service",IF($H16="Investor Owned",IF(AND(COUNTIF(Parameters!$A$4:$A$33,$G16)>0,COUNTIF(Parameters!$B$4:$B$33,$B16)=0),"procurement","cost_service"),"unclassified"))))))
A17: 2024 | B17: 13374 | C17: Constellation NewEnergy, Inc | D17: B | E17: Energy | F17: O | G17: PA | H17: Retail Power Marketer | I17: PJM | J17: 61610.7 | K17: 593218 | L17: 53821 | M17: 1380249.1 | N17: 19290687 | O17: 81982 | P17: 180491.1 | Q17: 2854913 | R17: 1102 | S17: 12008.3 | T17: 148548 | U17: 1 | V17: 1634359.2 | W17: 22887366 | X17: 136906 | Y17: =IF(ISNUMBER($W17),$W17,0) | Z17: =IF(ISNUMBER(SEARCH("Adjustment",$C17)),"excluded",IF($H17="Behind the Meter","excluded",IF(NOT(OR($E17="Bundled",$E17="Energy")),"excluded",IF(OR($H17="Retail Power Marketer",$H17="Community Choice Aggregator",$E17="Energy"),"procurement",IF(OR($H17="Municipal",$H17="Cooperative",$H17="Federal",$H17="State",$H17="Political Subdivision"),"cost_service",IF($H17="Investor Owned",IF(AND(COUNTIF(Parameters!$A$4:$A$33,$G17)>0,COUNTIF(Parameters!$B$4:$B$33,$B17)=0),"procurement","cost_service"),"unclassified"))))))
A18: 2024 | B18: 14715 | C18: PPL Electric Utilities Corp | D18: A | E18: Bundled | F18: O | G18: PA | H18: Investor Owned | I18: PJM | J18: 1380991.7 | K18: 8128207 | L18: 797773 | M18: 262203.9 | N18: 1886520 | O18: 93479 | P18: 16938.7 | Q18: 154926 | R18: 856 | S18: 0 | T18: 0 | U18: 0 | V18: 1660134.3 | W18: 10169653 | X18: 892108 | Y18: =IF(ISNUMBER($W18),$W18,0) | Z18: =IF(ISNUMBER(SEARCH("Adjustment",$C18)),"excluded",IF($H18="Behind the Meter","excluded",IF(NOT(OR($E18="Bundled",$E18="Energy")),"excluded",IF(OR($H18="Retail Power Marketer",$H18="Community Choice Aggregator",$E18="Energy"),"procurement",IF(OR($H18="Municipal",$H18="Cooperative",$H18="Federal",$H18="State",$H18="Political Subdivision"),"cost_service",IF($H18="Investor Owned",IF(AND(COUNTIF(Parameters!$A$4:$A$33,$G18)>0,COUNTIF(Parameters!$B$4:$B$33,$B18)=0),"procurement","cost_service"),"unclassified"))))))
A19: 2024 | B19: 14715 | C19: PPL Electric Utilities Corp | D19: C | E19: Delivery | F19: O | G19: PA | H19: Investor Owned | I19: PJM | J19: 374734.4 | K19: 6098417 | L19: 498110 | M19: 193575.7 | N19: 12010707 | O19: 95036 | P19: 36574 | Q19: 8345169 | R19: 2093 | S19: 0 | T19: 0 | U19: 0 | V19: 604884.1 | W19: 26454293 | X19: 595239 | Y19: =IF(ISNUMBER($W19),$W19,0) | Z19: =IF(ISNUMBER(SEARCH("Adjustment",$C19)),"excluded",IF($H19="Behind the Meter","excluded",IF(NOT(OR($E19="Bundled",$E19="Energy")),"excluded",IF(OR($H19="Retail Power Marketer",$H19="Community Choice Aggregator",$E19="Energy"),"procurement",IF(OR($H19="Municipal",$H19="Cooperative",$H19="Federal",$H19="State",$H19="Political Subdivision"),"cost_service",IF($H19="Investor Owned",IF(AND(COUNTIF(Parameters!$A$4:$A$33,$G19)>0,COUNTIF(Parameters!$B$4:$B$33,$B19)=0),"procurement","cost_service"),"unclassified"))))))
A20: 2024 | B20: 14940 | C20: PECO Energy Co | D20: A | E20: Bundled | F20: O | G20: PA | H20: Investor Owned | I20: PJM | J20: 1752341 | K20: 10840952 | L20: 1205013 | M20: 311773.5 | N20: 2648121 | O20: 99909 | P20: 42395 | Q20: 561116 | R20: 394 | S20: 0 | T20: 0 | U20: 0 | V20: 2106509.5 | W20: 14050189 | X20: 1305316 | Y20: =IF(ISNUMBER($W20),$W20,0) | Z20: =IF(ISNUMBER(SEARCH("Adjustment",$C20)),"excluded",IF($H20="Behind the Meter","excluded",IF(NOT(OR($E20="Bundled",$E20="Energy")),"excluded",IF(OR($H20="Retail Power Marketer",$H20="Community Choice Aggregator",$E20="Energy"),"procurement",IF(OR($H20="Municipal",$H20="Cooperative",$H20="Federal",$H20="State",$H20="Political Subdivision"),"cost_service",IF($H20="Investor Owned",IF(AND(COUNTIF(Parameters!$A$4:$A$33,$G20)>0,COUNTIF(Parameters!$B$4:$B$33,$B20)=0),"procurement","cost_service"),"unclassified"))))))
A21: 2024 | B21: 14940 | C21: PECO Energy Co | D21: C | E21: Delivery | F21: O | G21: PA | H21: Investor Owned | I21: PJM | J21: 285785.8 | K21: 2981893 | L21: 330805 | M21: 198915.2 | N21: 4945199 | O21: 67420 | P21: 187861.4 | Q21: 12964540 | R21: 2755 | S21: 7078.3 | T21: 469922 | U21: 3 | V21: 679640.7 | W21: 21361554 | X21: 400983 | Y21: =IF(ISNUMBER($W21),$W21,0) | Z21: =IF(ISNUMBER(SEARCH("Adjustment",$C21)),"excluded",IF($H21="Behind the Meter","excluded",IF(NOT(OR($E21="Bundled",$E21="Energy")),"excluded",IF(OR($H21="Retail Power Marketer",$H21="Community Choice Aggregator",$E21="Energy"),"procurement",IF(OR($H21="Municipal",$H21="Cooperative",$H21="Federal",$H21="State",$H21="Political Subdivision"),"cost_service",IF($H21="Investor Owned",IF(AND(COUNTIF(Parameters!$A$4:$A$33,$G21)>0,COUNTIF(Parameters!$B$4:$B$33,$B21)=0),"procurement","cost_service"),"unclassified"))))))
A22: 2024 | B22: 15045 | C22: Pike County Light & Power Co | D22: A | E22: Bundled | F22: O | G22: PA | H22: Investor Owned | I22: NYIS | J22: 5749.3 | K22: 28824 | L22: 3646 | M22: 7035 | N22: 40496 | O22: 799 | P22: 0 | Q22: 0 | R22: 0 | S22: 0 | T22: 0 | U22: 0 | V22: 12784.3 | W22: 69320 | X22: 4445 | Y22: =IF(ISNUMBER($W22),$W22,0) | Z22: =IF(ISNUMBER(SEARCH("Adjustment",$C22)),"excluded",IF($H22="Behind the Meter","excluded",IF(NOT(OR($E22="Bundled",$E22="Energy")),"excluded",IF(OR($H22="Retail Power Marketer",$H22="Community Choice Aggregator",$E22="Energy"),"procurement",IF(OR($H22="Municipal",$H22="Cooperative",$H22="Federal",$H22="State",$H22="Political Subdivision"),"cost_service",IF($H22="Investor Owned",IF(AND(COUNTIF(Parameters!$A$4:$A$33,$G22)>0,COUNTIF(Parameters!$B$4:$B$33,$B22)=0),"procurement","cost_service"),"unclassified"))))))
A23: 2024 | B23: 15045 | C23: Pike County Light & Power Co | D23: C | E23: Delivery | F23: O | G23: PA | H23: Investor Owned | I23: NYIS | J23: 629.8 | K23: 5368 | L23: 701 | M23: 714.6 | N23: 6934 | O23: 216 | P23: 0 | Q23: 0 | R23: 0 | S23: 0 | T23: 0 | U23: 0 | V23: 1344.4 | W23: 12302 | X23: 917 | Y23: =IF(ISNUMBER($W23),$W23,0) | Z23: =IF(ISNUMBER(SEARCH("Adjustment",$C23)),"excluded",IF($H23="Behind the Meter","excluded",IF(NOT(OR($E23="Bundled",$E23="Energy")),"excluded",IF(OR($H23="Retail Power Marketer",$H23="Community Choice Aggregator",$E23="Energy"),"procurement",IF(OR($H23="Municipal",$H23="Cooperative",$H23="Federal",$H23="State",$H23="Political Subdivision"),"cost_service",IF($H23="Investor Owned",IF(AND(COUNTIF(Parameters!$A$4:$A$33,$G23)>0,COUNTIF(Parameters!$B$4:$B$33,$B23)=0),"procurement","cost_service"),"unclassified"))))))
A24: 2024 | B24: 16840 | C24: Calpine Energy Solutions, LLC | D24: B | E24: Energy | F24: O | G24: PA | H24: Retail Power Marketer | I24: PJM | J24: 0 | K24: 0 | L24: 0 | M24: 241453.8 | N24: 4459656 | O24: 67 | P24: 19502.9 | Q24: 347804 | R24: 9 | S24: 0 | T24: 0 | U24: 0 | V24: 260956.7 | W24: 4807460 | X24: 76 | Y24: =IF(ISNUMBER($W24),$W24,0) | Z24: =IF(ISNUMBER(SEARCH("Adjustment",$C24)),"excluded",IF($H24="Behind the Meter","excluded",IF(NOT(OR($E24="Bundled",$E24="Energy")),"excluded",IF(OR($H24="Retail Power Marketer",$H24="Community Choice Aggregator",$E24="Energy"),"procurement",IF(OR($H24="Municipal",$H24="Cooperative",$H24="Federal",$H24="State",$H24="Political Subdivision"),"cost_service",IF($H24="Investor Owned",IF(AND(COUNTIF(Parameters!$A$4:$A$33,$G24)>0,COUNTIF(Parameters!$B$4:$B$33,$B24)=0),"procurement","cost_service"),"unclassified"))))))
A25: 2024 | B25: 18193 | C25: Direct Energy Business | D25: B | E25: Energy | F25: O | G25: PA | H25: Retail Power Marketer | I25: PJM | J25: 0 | K25: 0 | L25: 0 | M25: 135657.5 | N25: 1599928 | O25: 6331 | P25: 459153.2 | Q25: 6409008 | R25: 717 | S25: 0 | T25: 0 | U25: 0 | V25: 594810.7 | W25: 8008936 | X25: 7048 | Y25: =IF(ISNUMBER($W25),$W25,0) | Z25: =IF(ISNUMBER(SEARCH("Adjustment",$C25)),"excluded",IF($H25="Behind the Meter","excluded",IF(NOT(OR($E25="Bundled",$E25="Energy")),"excluded",IF(OR($H25="Retail Power Marketer",$H25="Community Choice Aggregator",$E25="Energy"),"procurement",IF(OR($H25="Municipal",$H25="Cooperative",$H25="Federal",$H25="State",$H25="Political Subdivision"),"cost_service",IF($H25="Investor Owned",IF(AND(COUNTIF(Parameters!$A$4:$A$33,$G25)>0,COUNTIF(Parameters!$B$4:$B$33,$B25)=0),"procurement","cost_service"),"unclassified"))))))
A26: 2024 | B26: 19107 | C26: ENGIE Resources LLC | D26: B | E26: Energy | F26: O | G26: PA | H26: Retail Power Marketer | I26: PJM | J26: 0 | K26: 0 | L26: 0 | M26: 280552.2 | N26: 4137884 | O26: 3424 | P26: 28086.1 | Q26: 414244 | R26: 343 | S26: 0 | T26: 0 | U26: 0 | V26: 308638.3 | W26: 4552128 | X26: 3767 | Y26: =IF(ISNUMBER($W26),$W26,0) | Z26: =IF(ISNUMBER(SEARCH("Adjustment",$C26)),"excluded",IF($H26="Behind the Meter","excluded",IF(NOT(OR($E26="Bundled",$E26="Energy")),"excluded",IF(OR($H26="Retail Power Marketer",$H26="Community Choice Aggregator",$E26="Energy"),"procurement",IF(OR($H26="Municipal",$H26="Cooperative",$H26="Federal",$H26="State",$H26="Political Subdivision"),"cost_service",IF($H26="Investor Owned",IF(AND(COUNTIF(Parameters!$A$4:$A$33,$G26)>0,COUNTIF(Parameters!$B$4:$B$33,$B26)=0),"procurement","cost_service"),"unclassified"))))))
... A32: 2024 | B32: 20659 | C32: WGL Energy Services, Inc. | D32: B | E32: Energy | F32: O | G32: PA | H32: Retail Power Marketer | I32: PJM | J32: 6386 | K32: 98555 | L32: 11403 | M32: 313159 | N32: 4489731 | O32: 21575 | P32: 0 | Q32: 0 | R32: 0 | S32: 0 | T32: 0 | U32: 0 | V32: 319545 | W32: 4588286 | X32: 32978 | Y32: =IF(ISNUMBER($W32),$W32,0) | Z32: =IF(ISNUMBER(SEARCH("Adjustment",$C32)),"excluded",IF($H32="Behind the Meter","excluded",IF(NOT(OR($E32="Bundled",$E32="Energy")),"excluded",IF(OR($H32="Retail Power Marketer",$H32="Community Choice Aggregator",$E32="Energy"),"procurement",IF(OR($H32="Municipal",$H32="Cooperative",$H32="Federal",$H32="State",$H32="Political Subdivision"),"cost_service",IF($H32="Investor Owned",IF(AND(COUNTIF(Parameters!$A$4:$A$33,$G32)>0,COUNTIF(Parameters!$B$4:$B$33,$B32)=0),"procurement","cost_service"),"unclassified"))))))
A33: 2024 | B33: 28802 | C33: Talen Energy Marketing, LLC | D33: B | E33: Energy | F33: O | G33: PA | H33: Retail Power Marketer | I33: PJM | J33: . | K33: . | L33: . | M33: . | N33: . | O33: . | P33: 1429 | Q33: 34777 | R33: 4 | S33: . | T33: . | U33: . | V33: 1429 | W33: 34777 | X33: 4 | Y33: =IF(ISNUMBER($W33),$W33,0) | Z33: =IF(ISNUMBER(SEARCH("Adjustment",$C33)),"excluded",IF($H33="Behind the Meter","excluded",IF(NOT(OR($E33="Bundled",$E33="Energy")),"excluded",IF(OR($H33="Retail Power Marketer",$H33="Community Choice Aggregator",$E33="Energy"),"procurement",IF(OR($H33="Municipal",$H33="Cooperative",$H33="Federal",$H33="State",$H33="Political Subdivision"),"cost_service",IF($H33="Investor Owned",IF(AND(COUNTIF(Parameters!$A$4:$A$33,$G33)>0,COUNTIF(Parameters!$B$4:$B$33,$B33)=0),"procurement","cost_service"),"unclassified"))))))
A34: 2024 | B34: 40167 | C34: Somerset Rural Elec Coop, Inc | D34: A | E34: Bundled | F34: O | G34: PA | H34: Cooperative | I34: PJM | J34: 17484 | K34: 125202 | L34: 12322 | M34: 6517 | N34: 52872 | O34: 1578 | P34: 1695 | Q34: 17226 | R34: 3 | S34: . | T34: . | U34: . | V34: 25696 | W34: 195300 | X34: 13903 | Y34: =IF(ISNUMBER($W34),$W34,0) | Z34: =IF(ISNUMBER(SEARCH("Adjustment",$C34)),"excluded",IF($H34="Behind the Meter","excluded",IF(NOT(OR($E34="Bundled",$E34="Energy")),"excluded",IF(OR($H34="Retail Power Marketer",$H34="Community Choice Aggregator",$E34="Energy"),"procurement",IF(OR($H34="Municipal",$H34="Cooperative",$H34="Federal",$H34="State",$H34="Political Subdivision"),"cost_service",IF($H34="Investor Owned",IF(AND(COUNTIF(Parameters!$A$4:$A$33,$G34)>0,COUNTIF(Parameters!$B$4:$B$33,$B34)=0),"procurement","cost_service"),"unclassified"))))))
A35: 2024 | B35: 40220 | C35: Adams Electric Cooperative Inc | D35: A | E35: Bundled | F35: O | G35: PA | H35: Cooperative | I35: PJM | J35: 64263 | K35: 445525 | L35: 32231 | M35: 11393 | N35: 86441 | O35: 2289 | P35: 4368 | Q35: 42873 | R35: 14 | S35: . | T35: . | U35: . | V35: 80024 | W35: 574839 | X35: 34534 | Y35: =IF(ISNUMBER($W35),$W35,0) | Z35: =IF(ISNUMBER(SEARCH("Adjustment",$C35)),"excluded",IF($H35="Behind the Meter","excluded",IF(NOT(OR($E35="Bundled",$E35="Energy")),"excluded",IF(OR($H35="Retail Power Marketer",$H35="Community Choice Aggregator",$E35="Energy"),"procurement",IF(OR($H35="Municipal",$H35="Cooperative",$H35="Federal",$H35="State",$H35="Political Subdivision"),"cost_service",IF($H35="Investor Owned",IF(AND(COUNTIF(Parameters!$A$4:$A$33,$G35)>0,COUNTIF(Parameters!$B$4:$B$33,$B35)=0),"procurement","cost_service"),"unclassified"))))))
A36: 2024 | B36: 40221 | C36: Bedford Rural Elec Coop, Inc | D36: A | E36: Bundled | F36: O | G36: PA | H36: Cooperative | I36: PJM | J36: 14457 | K36: 99379 | L36: 8837 | M36: 3947 | N36: 31218 | O36: 743 | P36: 10568 | Q36: 100908 | R36: 2 | S36: . | T36: . | U36: . | V36: 28972 | W36: 231505 | X36: 9582 | Y36: =IF(ISNUMBER($W36),$W36,0) | Z36: =IF(ISNUMBER(SEARCH("Adjustment",$C36)),"excluded",IF($H36="Behind the Meter","excluded",IF(NOT(OR($E36="Bundled",$E36="Energy")),"excluded",IF(OR($H36="Retail Power Marketer",$H36="Community Choice Aggregator",$E36="Energy"),"procurement",IF(OR($H36="Municipal",$H36="Cooperative",$H36="Federal",$H36="State",$H36="Political Subdivision"),"cost_service",IF($H36="Investor Owned",IF(AND(COUNTIF(Parameters!$A$4:$A$33,$G36)>0,COUNTIF(Parameters!$B$4:$B$33,$B36)=0),"procurement","cost_service"),"unclassified"))))))
A37: 2024 | B37: 40222 | C37: Valley Rural Electric Coop Inc | D37: A | E37: Bundled | F37: O | G37: PA | H37: Cooperative | I37: PJM | J37: 30509 | K37: 205157 | L37: 18180 | M37: 10919 | N37: 76843 | O37: 4403 | P37: 489 | Q37: 3955 | R37: 2 | S37: . | T37: . | U37: . | V37: 41917 | W37: 285955 | X37: 22585 | Y37: =IF(ISNUMBER($W37),$W37,0) | Z37: =IF(ISNUMBER(SEARCH("Adjustment",$C37)),"excluded",IF($H37="Behind the Meter","excluded",IF(NOT(OR($E37="Bundled",$E37="Energy")),"excluded",IF(OR($H37="Retail Power Marketer",$H37="Community Choice Aggregator",$E37="Energy"),"procurement",IF(OR($H37="Municipal",$H37="Cooperative",$H37="Federal",$H37="State",$H37="Political Subdivision"),"cost_service",IF($H37="Investor Owned",IF(AND(COUNTIF(Parameters!$A$4:$A$33,$G37)>0,COUNTIF(Parameters!$B$4:$B$33,$B37)=0),"procurement","cost_service"),"unclassified"))))))
A38: 2024 | B38: 40224 | C38: Central Electric Coop, Inc - (PA) | D38: A | E38: Bundled | F38: O | G38: PA | H38: Cooperative | I38: PJM | J38: 36790 | K38: 216051 | L38: 23629 | M38: 9073 | N38: 65626 | O38: 1966 | P38: 2451 | Q38: 21309 | R38: 9 | S38: . | T38: . | U38: . | V38: 48314 | W38: 302986 | X38: 25604 | Y38: =IF(ISNUMBER($W38),$W38,0) | Z38: =IF(ISNUMBER(SEARCH("Adjustment",$C38)),"excluded",IF($H38="Behind the Meter","excluded",IF(NOT(OR($E38="Bundled",$E38="Energy")),"excluded",IF(OR($H38="Retail Power Marketer",$H38="Community Choice Aggregator",$E38="Energy"),"procurement",IF(OR($H38="Municipal",$H38="Cooperative",$H38="Federal",$H38="State",$H38="Political Subdivision"),"cost_service",IF($H38="Investor Owned",IF(AND(COUNTIF(Parameters!$A$4:$A$33,$G38)>0,COUNTIF(Parameters!$B$4:$B$33,$B38)=0),"procurement","cost_service"),"unclassified"))))))
A39: 2024 | B39: 40289 | C39: Claverack Rural Elec Coop Inc | D39: A | E39: Bundled | F39: O | G39: PA | H39: Cooperative | I39: PJM | J39: 30449 | K39: 166838 | L39: 16742 | M39: 9650 | N39: 70184 | O39: 2365 | P39: 7024 | Q39: 77359 | R39: 4 | S39: . | T39: . | U39: . | V39: 47123 | W39: 314381 | X39: 19111 | Y39: =IF(ISNUMBER($W39),$W39,0) | Z39: =IF(ISNUMBER(SEARCH("Adjustment",$C39)),"excluded",IF($H39="Behind the Meter","excluded",IF(NOT(OR($E39="Bundled",$E39="Energy")),"excluded",IF(OR($H39="Retail Power Marketer",$H39="Community Choice Aggregator",$E39="Energy"),"procurement",IF(OR($H39="Municipal",$H39="Cooperative",$H39="Federal",$H39="State",$H39="Political Subdivision"),"cost_service",IF($H39="Investor Owned",IF(AND(COUNTIF(Parameters!$A$4:$A$33,$G39)>0,COUNTIF(Parameters!$B$4:$B$33,$B39)=0),"procurement","cost_service"),"unclassified"))))))
A40: 2024 | B40: 40290 | C40: Tri-County Rural Elec Coop Inc (PA) | D40: A | E40: Bundled | F40: O | G40: PA | H40: Cooperative | I40: PJM | J40: 24934 | K40: 124161 | L40: 18206 | M40: 7686 | N40: 59371 | O40: 1352 | P40: 3121 | Q40: 33664 | R40: 4 | S40: . | T40: . | U40: . | V40: 35741 | W40: 217196 | X40: 19562 | Y40: =IF(ISNUMBER($W40),$W40,0) | Z40: =IF(ISNUMBER(SEARCH("Adjustment",$C40)),"excluded",IF($H40="Behind the Meter","excluded",IF(NOT(OR($E40="Bundled",$E40="Energy")),"excluded",IF(OR($H40="Retail Power Marketer",$H40="Community Choice Aggregator",$E40="Energy"),"procurement",IF(OR($H40="Municipal",$H40="Cooperative",$H40="Federal",$H40="State",$H40="Political Subdivision"),"cost_service",IF($H40="Investor Owned",IF(AND(COUNTIF(Parameters!$A$4:$A$33,$G40)>0,COUNTIF(Parameters!$B$4:$B$33,$B40)=0),"procurement","cost_service"),"unclassified"))))))
A41: 2024 | B41: 40292 | C41: REA Energy Coop Inc | D41: A | E41: Bundled | F41: O | G41: PA | H41: Cooperative | I41: PJM | J41: 33963 | K41: 233726 | L41: 20932 | M41: 8050 | N41: 64486 | O41: 1891 | P41: 9275 | Q41: 81845 | R41: 13 | S41: . | T41: . | U41: . | V41: 51288 | W41: 380057 | X41: 22836 | Y41: =IF(ISNUMBER($W41),$W41,0) | Z41: =IF(ISNUMBER(SEARCH("Adjustment",$C41)),"excluded",IF($H41="Behind the Meter","excluded",IF(NOT(OR($E41="Bundled",$E41="Energy")),"excluded",IF(OR($H41="Retail Power Marketer",$H41="Community Choice Aggregator",$E41="Energy"),"procurement",IF(OR($H41="Municipal",$H41="Cooperative",$H41="Federal",$H41="State",$H41="Political Subdivision"),"cost_service",IF($H41="Investor Owned",IF(AND(COUNTIF(Parameters!$A$4:$A$33,$G41)>0,COUNTIF(Parameters!$B$4:$B$33,$B41)=0),"procurement","cost_service"),"unclassified"))))))
A42: 2024 | B42: 40293 | C42: Northwestern Rural E C A, Inc - (PA) | D42: A | E42: Bundled | F42: O | G42: PA | H42: Cooperative | I42: PJM | J42: 30333 | K42: 194697 | L42: 18190 | M42: 6260 | N42: 43111 | O42: 1428 | P42: 1099 | Q42: 10760 | R42: 3 | S42: . | T42: . | U42: . | V42: 37692 | W42: 248568 | X42: 19621 | Y42: =IF(ISNUMBER($W42),$W42,0) | Z42: =IF(ISNUMBER(SEARCH("Adjustment",$C42)),"excluded",IF($H42="Behind the Meter","excluded",IF(NOT(OR($E42="Bundled",$E42="Energy")),"excluded",IF(OR($H42="Retail Power Marketer",$H42="Community Choice Aggregator",$E42="Energy"),"procurement",IF(OR($H42="Municipal",$H42="Cooperative",$H42="Federal",$H42="State",$H42="Political Subdivision"),"cost_service",IF($H42="Investor Owned",IF(AND(COUNTIF(Parameters!$A$4:$A$33,$G42)>0,COUNTIF(Parameters!$B$4:$B$33,$B42)=0),"procurement","cost_service"),"unclassified"))))))
A43: 2024 | B43: 49730 | C43: American PowerNet | D43: B | E43: Energy | F43: O | G43: PA | H43: Retail Power Marketer | I43: PJM | J43: 0 | K43: 0 | L43: 0 | M43: 26552.7 | N43: 442499 | O43: 14 | P43: 14050.6 | Q43: 224081 | R43: 6 | S43: 0 | T43: 0 | U43: 0 | V43: 40603.3 | W43: 666580 | X43: 20 | Y43: =IF(ISNUMBER($W43),$W43,0) | Z43: =IF(ISNUMBER(SEARCH("Adjustment",$C43)),"excluded",IF($H43="Behind the Meter","excluded",IF(NOT(OR($E43="Bundled",$E43="Energy")),"excluded",IF(OR($H43="Retail Power Marketer",$H43="Community Choice Aggregator",$E43="Energy"),"procurement",IF(OR($H43="Municipal",$H43="Cooperative",$H43="Federal",$H43="State",$H43="Political Subdivision"),"cost_service",IF($H43="Investor Owned",IF(AND(COUNTIF(Parameters!$A$4:$A$33,$G43)>0,COUNTIF(Parameters!$B$4:$B$33,$B43)=0),"procurement","cost_service"),"unclassified"))))))
A44: 2024 | B44: 49746 | C44: The Energy Coop | D44: B | E44: Energy | F44: O | G44: PA | H44: Cooperative | I44: PJM | J44: 2594.4 | K44: 18866 | L44: 2515 | M44: 240.7 | N44: 1794 | O44: 144 | P44: 0 | Q44: 0 | R44: 0 | S44: 0 | T44: 0 | U44: 0 | V44: 2835.1 | W44: 20660 | X44: 2659 | Y44: =IF(ISNUMBER($W44),$W44,0) | Z44: =IF(ISNUMBER(SEARCH("Adjustment",$C44)),"excluded",IF($H44="Behind the Meter","excluded",IF(NOT(OR($E44="Bundled",$E44="Energy")),"excluded",IF(OR($H44="Retail Power Marketer",$H44="Community Choice Aggregator",$E44="Energy"),"procurement",IF(OR($H44="Municipal",$H44="Cooperative",$H44="Federal",$H44="State",$H44="Political Subdivision"),"cost_service",IF($H44="Investor Owned",IF(AND(COUNTIF(Parameters!$A$4:$A$33,$G44)>0,COUNTIF(Parameters!$B$4:$B$33,$B44)=0),"procurement","cost_service"),"unclassified"))))))
A45: 2024 | B45: 50046 | C45: Texas Retail Energy, LLC | D45: B | E45: Energy | F45: O | G45: PA | H45: Retail Power Marketer | I45: PJM | J45: 0 | K45: 0 | L45: 0 | M45: 39085.2 | N45: 552152 | O45: 217 | P45: 0 | Q45: 0 | R45: 0 | S45: 0 | T45: 0 | U45: 0 | V45: 39085.2 | W45: 552152 | X45: 217 | Y45: =IF(ISNUMBER($W45),$W45,0) | Z45: =IF(ISNUMBER(SEARCH("Adjustment",$C45)),"excluded",IF($H45="Behind the Meter","excluded",IF(NOT(OR($E45="Bundled",$E45="Energy")),"excluded",IF(OR($H45="Retail Power Marketer",$H45="Community Choice Aggregator",$E45="Energy"),"procurement",IF(OR($H45="Municipal",$H45="Cooperative",$H45="Federal",$H45="State",$H45="Political Subdivision"),"cost_service",IF($H45="Investor Owned",IF(AND(COUNTIF(Parameters!$A$4:$A$33,$G45)>0,COUNTIF(Parameters!$B$4:$B$33,$B45)=0),"procurement","cost_service"),"unclassified"))))))
...

Sheet Share
A1: region | B1: cost_service_mwh | C1: procurement_mwh | D1: total_mwh | E1: share_cost_service | F1: share_procurement
A2: PA | B2: =SUMIFS('EIA-861 Sales 2024'!$Y$4:$Y$143,'EIA-861 Sales 2024'!$Z$4:$Z$143,"cost_service") | C2: =SUMIFS('EIA-861 Sales 2024'!$Y$4:$Y$143,'EIA-861 Sales 2024'!$Z$4:$Z$143,"procurement") | D2: =B2+C2 | E2: =IF($D2=0,0,B2/$D2) | F2: =IF($D2=0,0,C2/$D2)

Sheet SoEDtICoS
A1: Unit: dimensionless (% of demand) | B1: 2021 | C1: 2022 | D1: 2023 | E1: 2024 | F1: 2025 | G1: 2026 | H1: 2027 | I1: 2028 | J1: 2029 | K1: 2030 | L1: 2031 | M1: 2032 | N1: 2033 | O1: 2034 | P1: 2035 | Q1: 2036 | R1: 2037 | S1: 2038 | T1: 2039 | U1: 2040 | V1: 2041 | W1: 2042 | X1: 2043 | Y1: 2044 | Z1: 2045 | AA1: 2046 | AB1: 2047 | AC1: 2048 | AD1: 2049 | AE1: 2050
A2: Share that is Cost of Service | B2: =ROUND('Share'!$E$2,3) | C2: =ROUND('Share'!$E$2,3) | D2: =ROUND('Share'!$E$2,3) | E2: =ROUND('Share'!$E$2,3) | F2: =ROUND('Share'!$E$2,3) | G2: =ROUND('Share'!$E$2,3) | H2: =ROUND('Share'!$E$2,3) | I2: =ROUND('Share'!$E$2,3) | ... AE2: =ROUND('Share'!$E$2,3)
