Workbook

Sheet About
A1: HOIpTP - Health Outcome Incidence per Ton Pollutant (state, 2024-2050) | B1: Pennsylvania
A2: State code (derived): | B2: =IFERROR(INDEX(Geography!B:B, MATCH($B$1, Geography!C:C, 0)), "") -> PA
A5: Methodology (see docs/methodology/HOIpTP.md):
A6: incidents_per_ton[outcome, sector, pollutant]
A7: = SUM(avoided_incidents over active state counties)
A8: / SUM(pollutant_tons_reduced over active state counties)
A9: Per-state EPA COBRA runs (50% pollutant reduction in state, in-state receptors only).
A11: Outputs: 15 tabs (5 sectors x 3 pollutants), each 11 health outcomes x 27 years.
A12: Sectors: transport, electricity, buildings, industry, LULUCF.
A13: Pollutants: PM25, NOx, SO2.
A14: LULUCF sector reuses Industry NOx values (legacy convention).
A16: Year columns = state 2024 anchor x (eps-us national year value / eps-us 2024), so the
A17: per-ton rate follows the national trajectory (baseline incidence and population).
A19: Degenerate-run substitution (2026-09-14, TODOS O77):
... A48: Build: outputs/HOIpTP/_build_hoiptp_workbook.py

Sheet Keys
A1: Constants used by formulas elsewhere in this workbook. Change a value here, never inside a formula.
A2: category | B2: key | C2: value | D2: description
A3: substitution | B3: denominator_floor_tons | C3: 1 | D3: A COBRA run that reduced fewer tons than this has no usable denominator; its factor is replaced by the substitute run. Set low enough to catch only degenerate runs (VT electricity SO2 reduced 1.35e-5 t). 10 t would also override ten small-state pairs whose ratios are plausible.
A4: substitution | B4: max_ratio_to_us | C4: 20 | D4: Substitute when the state premature-mortality factor exceeds this multiple of the eps-us national factor for the same sector and pollutant. State runs count in-state receptors only, so a factor far ABOVE national is not credible.
A5: substitution | B5: min_ratio_to_us | C5: 0.0001 | D5: Substitute when the state factor is below this fraction of the eps-us national factor (a run whose concentration change rounded to zero). Small-state NOx factors legitimately sit at 0.1-1% of national; this must stay below them.
A6: substitution | B6: anchor_outcome | C6: Premature mortality | D6: Outcome row used for the ratio tests (the US_national_yearly key ends with it).
A7: substitution | B7: anchor_year | C7: 2024 | D7: Year of the state anchor and of the eps-us value used in the ratio tests.
A8: substitution | B8: key_separator | C8: | | D8: Separator used in US_national_yearly lookup keys and the COBRA_aggregated state|run key.
A9: substitution | B9: reason_floor | C9: tons reduced below floor; | D9: Text shown on COBRA_aggregated when the floor test fires.
A10: substitution | B10: reason_high | C10: factor above max multiple of US; | D10: Text shown when the upper ratio test fires.
A11: substitution | B11: reason_low | C11: factor below min fraction of US; | D11: Text shown when the lower ratio test fires.

Sheet Geography
A1: state_fips | B1: state_abbr | C1: state_name | D1: division_num | E1: division_name
A2: 01 | B2: AL | C2: Alabama | D2: 6 | E2: East South Central
A3: 04 | B3: AZ | C3: Arizona | D3: 9 | E3: Mountain South
A4: 05 | B4: AR | C4: Arkansas | D4: 7 | E4: West South Central
A5: 06 | B5: CA | C5: California | D5: 10 | E5: Pacific
A6: 08 | B6: CO | C6: Colorado | D6: 8 | E6: Mountain North
A7: 09 | B7: CT | C7: Connecticut | D7: 1 | E7: New England
A8: 10 | B8: DE | C8: Delaware | D8: 5 | E8: South Atlantic
A9: 12 | B9: FL | C9: Florida | D9: 5 | E9: South Atlantic
A10: 13 | B10: GA | C10: Georgia | D10: 5 | E10: South Atlantic
A11: 16 | B11: ID | C11: Idaho | D11: 8 | E11: Mountain North
A12: 17 | B12: IL | C12: Illinois | D12: 3 | E12: East North Central
A13: 18 | B13: IN | C13: Indiana | D13: 3 | E13: East North Central
... A49: 56 | B49: WY | C49: Wyoming | D49: 8 | E49: Mountain North

Sheet Runs
A1: The 12 state COBRA runs. Column E names the run whose factor replaces a degenerate run (same state, Industry sector, same pollutant). Column F is the US_national_yearly key for the ratio tests.
A2: run | B2: sector (workbook name) | C2: pollutant (tab suffix) | D2: tons-reduced column on COBRA_aggregated | E2: substitute run | F2: eps-us lookup key sector | pollutant | anchor outcome
A3: transportation PM25 | B3: transport | C3: PM25 | D3: delta_PM25 | E3: Industry PM25 | F3: =$B3 & Keys!$C$8 & $C3 & Keys!$C$8 & Keys!$C$6 -> transport|PM25|Premature mortality
A4: transportation NO2 | B4: transport | C4: NOx | D4: delta_NO2 | E4: Industry NO2 | F4: =$B4 & Keys!$C$8 & $C4 & Keys!$C$8 & Keys!$C$6 -> transport|NOx|Premature mortality
A5: transportation SO2 | B5: transport | C5: SO2 | D5: delta_SO2 | E5: Industry SO2 | F5: =$B5 & Keys!$C$8 & $C5 & Keys!$C$8 & Keys!$C$6 -> transport|SO2|Premature mortality
A6: electricity PM25 | B6: electricity | C6: PM25 | D6: delta_PM25 | E6: Industry PM25 | F6: =$B6 & Keys!$C$8 & $C6 & Keys!$C$8 & Keys!$C$6 -> electricity|PM25|Premature mortality
A7: electricity NO2 | B7: electricity | C7: NOx | D7: delta_NO2 | E7: Industry NO2 | F7: =$B7 & Keys!$C$8 & $C7 & Keys!$C$8 & Keys!$C$6 -> electricity|NOx|Premature mortality
A8: electricity SO2 | B8: electricity | C8: SO2 | D8: delta_SO2 | E8: Industry SO2 | F8: =$B8 & Keys!$C$8 & $C8 & Keys!$C$8 & Keys!$C$6 -> electricity|SO2|Premature mortality
A9: buildings PM25 | B9: buildings | C9: PM25 | D9: delta_PM25 | E9: Industry PM25 | F9: =$B9 & Keys!$C$8 & $C9 & Keys!$C$8 & Keys!$C$6 -> buildings|PM25|Premature mortality
A10: buildings NO2 | B10: buildings | C10: NOx | D10: delta_NO2 | E10: Industry NO2 | F10: =$B10 & Keys!$C$8 & $C10 & Keys!$C$8 & Keys!$C$6 -> buildings|NOx|Premature mortality
A11: buildings SO2 | B11: buildings | C11: SO2 | D11: delta_SO2 | E11: Industry SO2 | F11: =$B11 & Keys!$C$8 & $C11 & Keys!$C$8 & Keys!$C$6 -> buildings|SO2|Premature mortality
A12: Industry PM25 | B12: industry | C12: PM25 | D12: delta_PM25 | E12: Industry PM25 | F12: =$B12 & Keys!$C$8 & $C12 & Keys!$C$8 & Keys!$C$6 -> industry|PM25|Premature mortality
A13: Industry NO2 | B13: industry | C13: NOx | D13: delta_NO2 | E13: Industry NO2 | F13: =$B13 & Keys!$C$8 & $C13 & Keys!$C$8 & Keys!$C$6 -> industry|NOx|Premature mortality
A14: Industry SO2 | B14: industry | C14: SO2 | D14: delta_SO2 | E14: Industry SO2 | F14: =$B14 & Keys!$C$8 & $C14 & Keys!$C$8 & Keys!$C$6 -> industry|SO2|Premature mortality

Sheet COBRA_aggregated
A1: state | B1: run | C1: n_counties | D1: premature_mortality | E1: infant_mortality | F1: asthma_symptoms_cough | G1: asthma_symptoms_short_breath | H1: asthma_symptoms_wheeze | I1: resp_hospital_adm | J1: nonfatal_heart_attacks | K1: minor_restricted_activity | L1: work_loss_days | M1: cardio_hospital_adm | N1: asthma_exacerbation_total | O1: er_visits_asthma | P1: ha_asthma | Q1: ha_chronic_lung | R1: acute_bronchitis | S1: lower_resp_symptoms | T1: upper_resp_symptoms | U1: delta_PM25 | V1: delta_SO2 | W1: delta_NO2 | Y1: State and run key state | run | Z1: Tons the COBRA run actually reduced of the run's own pollutant | AA1: Premature deaths per ton, this run incidents / tons reduced | AB1: Premature deaths per ton, eps-us national same sector and pollutant, anchor year | AC1: State factor as a multiple of national own / US | AD1: TEST: too few tons reduced? 1 = below Keys floor | AE1: TEST: factor implausibly high? 1 = above Keys max multiple of US | AF1: TEST: factor rounded to nothing? 1 = below Keys min fraction of US | AG1: SUBSTITUTE THIS RUN? 1 = any test fired; output tabs use the substitute | AH1: Substitute run same state, Industry sector, same pollutant | AI1: RUN USED IN THE OUTPUT TABS substitute if flagged, else own run | AJ1: Why it was substituted blank = own run used | AK1: CHECK: is the substitute run itself flagged? 1 = problem
A2: Alabama | B2: Industry NO2 | C2: 67 | D2: 48.182545 | E2: 0.14567252 | F2: 104.34874 | G2: 140.51735 | H2: 214.69873 | I2: 4.2299062 | J2: 25.309846 | K2: 12800.531 | L2: 2161.6573 | M2: 5.3347775 | N2: 459.56483 | O2: 10.145233 | P2: 0.34378306 | Q2: 1.3581583 | R2: 24.394175 | S2: 310.15321 | T2: 441.3351 | U2: 0 | V2: 0 | W2: 59735.957 | Y2: =$A2 & Keys!$C$8 & $B2 -> Alabama|Industry NO2 | Z2: =IFERROR(INDEX($U2:$W2, MATCH(INDEX(Runs!$D:$D, MATCH($B2, Runs!$A:$A, 0)), $U$1:$W$1, 0)), 0) -> 59735.957 | AA2: =IFERROR($D2/$Z2, 0) -> 0.00080659199 | AB2: =IFERROR(VLOOKUP(INDEX(Runs!$F:$F, MATCH($B2, Runs!$A:$A, 0)), US_national_yearly!$D:$AM, MATCH(Keys!$C$7, US_national_yearly!$D$1:$AM$1, 0), FALSE), 0) -> 0.0058012217 | AC2: =IFERROR($AA2/$AB2, 0) -> 0.1390383 | AD2: =IF($Z2<Keys!$C$3, 1, 0) -> 0 | AE2: =IF($AC2>Keys!$C$4, 1, 0) -> 0 | AF2: =IF($AC2<Keys!$C$5, 1, 0) -> 0 | AG2: =IF($AD2+$AE2+$AF2>0, 1, 0) -> 0 | AH2: =IFERROR(INDEX(Runs!$E:$E, MATCH($B2, Runs!$A:$A, 0)), $B2) -> Industry NO2 | AI2: =IF($AG2=1, $AH2, $B2) -> Industry NO2 | AJ2: =IF($AG2=1, IF($AD2=1, Keys!$C$9, "") & IF($AE2=1, Keys!$C$10, "") & IF($AF2=1, Keys!$C$11, ""), "") | AK2: =IF($AG2=1, IFERROR(INDEX($AG$2:$AG$577, MATCH($A2 & Keys!$C$8 & $AH2, $Y$2:$Y$577, 0)), 1), 0) -> 0
A3: Alabama | B3: Industry PM25 | C3: 67 | D3: 121.27712 | E3: 0.38512663 | F3: 263.13127 | G3: 354.3188 | H3: 541.43043 | I3: 10.513268 | J3: 62.860316 | K3: 31993.698 | L3: 5407.5228 | M3: 13.278714 | N3: 1158.8805 | O3: 25.433111 | P3: 0.86805551 | Q3: 3.3879153 | R3: 61.534207 | S3: 782.73584 | T3: 1115.4642 | U3: 11808.201 | V3: 0 | W3: 0 | Y3: =$A3 & Keys!$C$8 & $B3 -> Alabama|Industry PM25 | Z3: =IFERROR(INDEX($U3:$W3, MATCH(INDEX(Runs!$D:$D, MATCH($B3, Runs!$A:$A, 0)), $U$1:$W$1, 0)), 0) -> 11808.201 | AA3: =IFERROR($D3/$Z3, 0) -> 0.010270584 | AB3: =IFERROR(VLOOKUP(INDEX(Runs!$F:$F, MATCH($B3, Runs!$A:$A, 0)), US_national_yearly!$D:$AM, MATCH(Keys!$C$7, US_national_yearly!$D$1:$AM$1, 0), FALSE), 0) -> 0.026833192 | AC3: =IFERROR($AA3/$AB3, 0) -> 0.38275669 | AD3: =IF($Z3<Keys!$C$3, 1, 0) -> 0 | AE3: =IF($AC3>Keys!$C$4, 1, 0) -> 0 | AF3: =IF($AC3<Keys!$C$5, 1, 0) -> 0 | AG3: =IF($AD3+$AE3+$AF3>0, 1, 0) -> 0 | AH3: =IFERROR(INDEX(Runs!$E:$E, MATCH($B3, Runs!$A:$A, 0)), $B3) -> Industry PM25 | AI3: =IF($AG3=1, $AH3, $B3) -> Industry PM25 | AJ3: =IF($AG3=1, IF($AD3=1, Keys!$C$9, "") & IF($AE3=1, Keys!$C$10, "") & IF($AF3=1, Keys!$C$11, ""), "") | AK3: =IF($AG3=1, IFERROR(INDEX($AG$2:$AG$577, MATCH($A3 & Keys!$C$8 & $AH3, $Y$2:$Y$577, 0)), 1), 0) -> 0
A4: Alabama | B4: Industry SO2 | C4: 67 | D4: 22.746684 | E4: 0.06996468 | F4: 49.571932 | G4: 66.755004 | H4: 101.99317 | I4: 1.975851 | J4: 11.835458 | K4: 6068.6856 | L4: 1025.6237 | M4: 2.4946669 | N4: 218.3201 | O4: 4.8070264 | P4: 0.1630608 | Q4: 0.63680331 | R4: 11.54994 | S4: 146.8207 | T4: 208.81722 | U4: 0 | V4: 30764.722 | W4: 0 | Y4: =$A4 & Keys!$C$8 & $B4 -> Alabama|Industry SO2 | Z4: =IFERROR(INDEX($U4:$W4, MATCH(INDEX(Runs!$D:$D, MATCH($B4, Runs!$A:$A, 0)), $U$1:$W$1, 0)), 0) -> 30764.722 | AA4: =IFERROR($D4/$Z4, 0) -> 0.00073937556 | AB4: =IFERROR(VLOOKUP(INDEX(Runs!$F:$F, MATCH($B4, Runs!$A:$A, 0)), US_national_yearly!$D:$AM, MATCH(Keys!$C$7, US_national_yearly!$D$1:$AM$1, 0), FALSE), 0) -> 0.0053000352 | AC4: =IFERROR($AA4/$AB4, 0) -> 0.1395039 | AD4: =IF($Z4<Keys!$C$3, 1, 0) -> 0 | AE4: =IF($AC4>Keys!$C$4, 1, 0) -> 0 | AF4: =IF($AC4<Keys!$C$5, 1, 0) -> 0 | AG4: =IF($AD4+$AE4+$AF4>0, 1, 0) -> 0 | AH4: =IFERROR(INDEX(Runs!$E:$E, MATCH($B4, Runs!$A:$A, 0)), $B4) -> Industry SO2 | AI4: =IF($AG4=1, $AH4, $B4) -> Industry SO2 | AJ4: =IF($AG4=1, IF($AD4=1, Keys!$C$9, "") & IF($AE4=1, Keys!$C$10, "") & IF($AF4=1, Keys!$C$11, ""), "") | AK4: =IF($AG4=1, IFERROR(INDEX($AG$2:$AG$577, MATCH($A4 & Keys!$C$8 & $AH4, $Y$2:$Y$577, 0)), 1), 0) -> 0
A5: Alabama | B5: buildings NO2 | C5: 67 | D5: 1.4641796 | E5: 0.004715075 | F5: 3.1957995 | G5: 4.3036094 | H5: 6.5751799 | I5: 0.12668289 | J5: 0.76115558 | K5: 388.54101 | L5: 65.668604 | M5: 0.16032138 | N5: 14.074589 | O5: 0.30865664 | P5: 0.010547297 | Q5: 0.041051973 | R5: 0.74981274 | S5: 9.5299034 | T5: 13.547899 | U5: 0 | V5: 0 | W5: 2300.011 | Y5: =$A5 & Keys!$C$8 & $B5 -> Alabama|buildings NO2 | Z5: =IFERROR(INDEX($U5:$W5, MATCH(INDEX(Runs!$D:$D, MATCH($B5, Runs!$A:$A, 0)), $U$1:$W$1, 0)), 0) -> 2300.011 | AA5: =IFERROR($D5/$Z5, 0) -> 0.00063659681 | AB5: =IFERROR(VLOOKUP(INDEX(Runs!$F:$F, MATCH($B5, Runs!$A:$A, 0)), US_national_yearly!$D:$AM, MATCH(Keys!$C$7, US_national_yearly!$D$1:$AM$1, 0), FALSE), 0) -> 0.005678474 | AC5: =IFERROR($AA5/$AB5, 0) -> 0.11210702 | AD5: =IF($Z5<Keys!$C$3, 1, 0) -> 0 | AE5: =IF($AC5>Keys!$C$4, 1, 0) -> 0 | AF5: =IF($AC5<Keys!$C$5, 1, 0) -> 0 | AG5: =IF($AD5+$AE5+$AF5>0, 1, 0) -> 0 | AH5: =IFERROR(INDEX(Runs!$E:$E, MATCH($B5, Runs!$A:$A, 0)), $B5) -> Industry NO2 | AI5: =IF($AG5=1, $AH5, $B5) -> buildings NO2 | AJ5: =IF($AG5=1, IF($AD5=1, Keys!$C$9, "") & IF($AE5=1, Keys!$C$10, "") & IF($AF5=1, Keys!$C$11, ""), "") | AK5: =IF($AG5=1, IFERROR(INDEX($AG$2:$AG$577, MATCH($A5 & Keys!$C$8 & $AH5, $Y$2:$Y$577, 0)), 1), 0) -> 0
A6: Alabama | B6: buildings PM25 | C6: 67 | D6: 0.20434763 | E6: 0.00070041114 | F6: 0.45240917 | G6: 0.60923528 | H6: 0.93080583 | I6: 0.017684284 | J6: 0.10651897 | K6: 54.736665 | L6: 9.2608898 | M6: 0.022443027 | N6: 1.9924503 | O6: 0.043547528 | P6: 0.0014972392 | Q6: 0.0057722426 | R6: 0.10655988 | S6: 1.3542553 | T6: 1.9250013 | U6: 13.831646 | V6: 0 | W6: 0 | Y6: =$A6 & Keys!$C$8 & $B6 -> Alabama|buildings PM25 | Z6: =IFERROR(INDEX($U6:$W6, MATCH(INDEX(Runs!$D:$D, MATCH($B6, Runs!$A:$A, 0)), $U$1:$W$1, 0)), 0) -> 13.831646 | AA6: =IFERROR($D6/$Z6, 0) -> 0.01477392 | AB6: =IFERROR(VLOOKUP(INDEX(Runs!$F:$F, MATCH($B6, Runs!$A:$A, 0)), US_national_yearly!$D:$AM, MATCH(Keys!$C$7, US_national_yearly!$D$1:$AM$1, 0), FALSE), 0) -> 0.027627705 | AC6: =IFERROR($AA6/$AB6, 0) -> 0.53475018 | AD6: =IF($Z6<Keys!$C$3, 1, 0) -> 0 | AE6: =IF($AC6>Keys!$C$4, 1, 0) -> 0 | AF6: =IF($AC6<Keys!$C$5, 1, 0) -> 0 | AG6: =IF($AD6+$AE6+$AF6>0, 1, 0) -> 0 | AH6: =IFERROR(INDEX(Runs!$E:$E, MATCH($B6, Runs!$A:$A, 0)), $B6) -> Industry PM25 | AI6: =IF($AG6=1, $AH6, $B6) -> buildings PM25 | AJ6: =IF($AG6=1, IF($AD6=1, Keys!$C$9, "") & IF($AE6=1, Keys!$C$10, "") & IF($AF6=1, Keys!$C$11, ""), "") | AK6: =IF($AG6=1, IFERROR(INDEX($AG$2:$AG$577, MATCH($A6 & Keys!$C$8 & $AH6, $Y$2:$Y$577, 0)), 1), 0) -> 0
A7: Alabama | B7: buildings SO2 | C7: 67 | D7: 0.049671379 | E7: 0.00016121822 | F7: 0.10779245 | G7: 0.14515835 | H7: 0.22177669 | I7: 0.0042865388 | J7: 0.02574153 | K7: 13.105917 | L7: 2.2151746 | M7: 0.0054219734 | N7: 0.47472749 | O7: 0.010414557 | P7: 0.00035598534 | Q7: 0.0013868006 | R7: 0.025319685 | S7: 0.32179768 | T7: 0.45744839 | U7: 0 | V7: 20.374251 | W7: 0 | Y7: =$A7 & Keys!$C$8 & $B7 -> Alabama|buildings SO2 | Z7: =IFERROR(INDEX($U7:$W7, MATCH(INDEX(Runs!$D:$D, MATCH($B7, Runs!$A:$A, 0)), $U$1:$W$1, 0)), 0) -> 20.374251 | AA7: =IFERROR($D7/$Z7, 0) -> 0.0024379487 | AB7: =IFERROR(VLOOKUP(INDEX(Runs!$F:$F, MATCH($B7, Runs!$A:$A, 0)), US_national_yearly!$D:$AM, MATCH(Keys!$C$7, US_national_yearly!$D$1:$AM$1, 0), FALSE), 0) -> 0.0051581943 | AC7: =IFERROR($AA7/$AB7, 0) -> 0.47263607 | AD7: =IF($Z7<Keys!$C$3, 1, 0) -> 0 | AE7: =IF($AC7>Keys!$C$4, 1, 0) -> 0 | AF7: =IF($AC7<Keys!$C$5, 1, 0) -> 0 | AG7: =IF($AD7+$AE7+$AF7>0, 1, 0) -> 0 | AH7: =IFERROR(INDEX(Runs!$E:$E, MATCH($B7, Runs!$A:$A, 0)), $B7) -> Industry SO2 | AI7: =IF($AG7=1, $AH7, $B7) -> buildings SO2 | AJ7: =IF($AG7=1, IF($AD7=1, Keys!$C$9, "") & IF($AE7=1, Keys!$C$10, "") & IF($AF7=1, Keys!$C$11, ""), "") | AK7: =IF($AG7=1, IFERROR(INDEX($AG$2:$AG$577, MATCH($A7 & Keys!$C$8 & $AH7, $Y$2:$Y$577, 0)), 1), 0) -> 0
A8: Alabama | B8: electricity NO2 | C8: 67 | D8: 2.8169282 | E8: 0.0084258762 | F8: 5.9137789 | G8: 7.9637609 | H8: 12.167279 | I8: 0.24311331 | J8: 1.4476322 | K8: 719.75616 | L8: 121.46169 | M8: 0.30486755 | N8: 26.044818 | O8: 0.5729668 | P8: 0.019475293 | Q8: 0.076787424 | R8: 1.3869015 | S8: 17.628432 | T8: 25.064214 | U8: 0 | V8: 0 | W8: 9758.9194 | Y8: =$A8 & Keys!$C$8 & $B8 -> Alabama|electricity NO2 | Z8: =IFERROR(INDEX($U8:$W8, MATCH(INDEX(Runs!$D:$D, MATCH($B8, Runs!$A:$A, 0)), $U$1:$W$1, 0)), 0) -> 9758.9194 | AA8: =IFERROR($D8/$Z8, 0) -> 0.00028865165 | AB8: =IFERROR(VLOOKUP(INDEX(Runs!$F:$F, MATCH($B8, Runs!$A:$A, 0)), US_national_yearly!$D:$AM, MATCH(Keys!$C$7, US_national_yearly!$D$1:$AM$1, 0), FALSE), 0) -> 0.0061439222 | AC8: =IFERROR($AA8/$AB8, 0) -> 0.046981659 | AD8: =IF($Z8<Keys!$C$3, 1, 0) -> 0 | AE8: =IF($AC8>Keys!$C$4, 1, 0) -> 0 | AF8: =IF($AC8<Keys!$C$5, 1, 0) -> 0 | AG8: =IF($AD8+$AE8+$AF8>0, 1, 0) -> 0 | AH8: =IFERROR(INDEX(Runs!$E:$E, MATCH($B8, Runs!$A:$A, 0)), $B8) -> Industry NO2 | AI8: =IF($AG8=1, $AH8, $B8) -> electricity NO2 | AJ8: =IF($AG8=1, IF($AD8=1, Keys!$C$9, "") & IF($AE8=1, Keys!$C$10, "") & IF($AF8=1, Keys!$C$11, ""), "") | AK8: =IF($AG8=1, IFERROR(INDEX($AG$2:$AG$577, MATCH($A8 & Keys!$C$8 & $AH8, $Y$2:$Y$577, 0)), 1), 0) -> 0
A9: Alabama | B9: electricity PM25 | C9: 67 | D9: 4.8850516 | E9: 0.014866662 | F9: 10.762432 | G9: 14.493133 | H9: 22.143206 | I9: 0.41767572 | J9: 2.5302703 | K9: 1324.6842 | L9: 223.43381 | M9: 0.5325932 | N9: 47.398771 | O9: 1.0443723 | P9: 0.035344163 | Q9: 0.13846964 | R9: 2.4941053 | S9: 31.69967 | T9: 45.067712 | U9: 860.88973 | V9: 0 | W9: 0 | Y9: =$A9 & Keys!$C$8 & $B9 -> Alabama|electricity PM25 | Z9: =IFERROR(INDEX($U9:$W9, MATCH(INDEX(Runs!$D:$D, MATCH($B9, Runs!$A:$A, 0)), $U$1:$W$1, 0)), 0) -> 860.88973 | AA9: =IFERROR($D9/$Z9, 0) -> 0.0056744219 | AB9: =IFERROR(VLOOKUP(INDEX(Runs!$F:$F, MATCH($B9, Runs!$A:$A, 0)), US_national_yearly!$D:$AM, MATCH(Keys!$C$7, US_national_yearly!$D$1:$AM$1, 0), FALSE), 0) -> 0.024252978 | AC9: =IFERROR($AA9/$AB9, 0) -> 0.23396804 | AD9: =IF($Z9<Keys!$C$3, 1, 0) -> 0 | AE9: =IF($AC9>Keys!$C$4, 1, 0) -> 0 | AF9: =IF($AC9<Keys!$C$5, 1, 0) -> 0 | AG9: =IF($AD9+$AE9+$AF9>0, 1, 0) -> 0 | AH9: =IFERROR(INDEX(Runs!$E:$E, MATCH($B9, Runs!$A:$A, 0)), $B9) -> Industry PM25 | AI9: =IF($AG9=1, $AH9, $B9) -> electricity PM25 | AJ9: =IF($AG9=1, IF($AD9=1, Keys!$C$9, "") & IF($AE9=1, Keys!$C$10, "") & IF($AF9=1, Keys!$C$11, ""), "") | AK9: =IF($AG9=1, IFERROR(INDEX($AG$2:$AG$577, MATCH($A9 & Keys!$C$8 & $AH9, $Y$2:$Y$577, 0)), 1), 0) -> 0
A10: Alabama | B10: electricity SO2 | C10: 67 | D10: 2.552738 | E10: 0.0081284011 | F10: 5.5009901 | G10: 7.4078795 | H10: 11.317991 | I10: 0.21864577 | J10: 1.3109717 | K10: 666.09382 | L10: 112.52043 | M10: 0.27611159 | N10: 24.226861 | O10: 0.53017982 | P10: 0.018137941 | Q10: 0.07044536 | R10: 1.2904801 | S10: 16.402114 | T10: 23.318932 | U10: 0 | V10: 4713.4685 | W10: 0 | Y10: =$A10 & Keys!$C$8 & $B10 -> Alabama|electricity SO2 | Z10: =IFERROR(INDEX($U10:$W10, MATCH(INDEX(Runs!$D:$D, MATCH($B10, Runs!$A:$A, 0)), $U$1:$W$1, 0)), 0) -> 4713.4685 | AA10: =IFERROR($D10/$Z10, 0) -> 0.00054158376 | AB10: =IFERROR(VLOOKUP(INDEX(Runs!$F:$F, MATCH($B10, Runs!$A:$A, 0)), US_national_yearly!$D:$AM, MATCH(Keys!$C$7, US_national_yearly!$D$1:$AM$1, 0), FALSE), 0) -> 0.005703233 | AC10: =IFERROR($AA10/$AB10, 0) -> 0.094960834 | AD10: =IF($Z10<Keys!$C$3, 1, 0) -> 0 | AE10: =IF($AC10>Keys!$C$4, 1, 0) -> 0 | AF10: =IF($AC10<Keys!$C$5, 1, 0) -> 0 | AG10: =IF($AD10+$AE10+$AF10>0, 1, 0) -> 0 | AH10: =IFERROR(INDEX(Runs!$E:$E, MATCH($B10, Runs!$A:$A, 0)), $B10) -> Industry SO2 | AI10: =IF($AG10=1, $AH10, $B10) -> electricity SO2 | AJ10: =IF($AG10=1, IF($AD10=1, Keys!$C$9, "") & IF($AE10=1, Keys!$C$10, "") & IF($AF10=1, Keys!$C$11, ""), "") | AK10: =IF($AG10=1, IFERROR(INDEX($AG$2:$AG$577, MATCH($A10 & Keys!$C$8 & $AH10, $Y$2:$Y$577, 0)), 1), 0) -> 0
A11: Alabama | B11: transportation NO2 | C11: 67 | D11: 41.292154 | E11: 0.12609375 | F11: 88.548937 | G11: 119.24172 | H11: 182.18924 | I11: 3.586008 | J11: 21.452483 | K11: 10818.397 | L11: 1826.5705 | M11: 4.5206815 | N11: 389.9799 | O11: 8.5878613 | P11: 0.29177466 | Q11: 1.149704 | R11: 20.719883 | S11: 263.40672 | T11: 374.71765 | U11: 0 | V11: 0 | W11: 78155.865 | Y11: =$A11 & Keys!$C$8 & $B11 -> Alabama|transportation NO2 | Z11: =IFERROR(INDEX($U11:$W11, MATCH(INDEX(Runs!$D:$D, MATCH($B11, Runs!$A:$A, 0)), $U$1:$W$1, 0)), 0) -> 78155.865 | AA11: =IFERROR($D11/$Z11, 0) -> 0.00052833084 | AB11: =IFERROR(VLOOKUP(INDEX(Runs!$F:$F, MATCH($B11, Runs!$A:$A, 0)), US_national_yearly!$D:$AM, MATCH(Keys!$C$7, US_national_yearly!$D$1:$AM$1, 0), FALSE), 0) -> 0.0057148836 | AC11: =IFERROR($AA11/$AB11, 0) -> 0.092448225 | AD11: =IF($Z11<Keys!$C$3, 1, 0) -> 0 | AE11: =IF($AC11>Keys!$C$4, 1, 0) -> 0 | AF11: =IF($AC11<Keys!$C$5, 1, 0) -> 0 | AG11: =IF($AD11+$AE11+$AF11>0, 1, 0) -> 0 | AH11: =IFERROR(INDEX(Runs!$E:$E, MATCH($B11, Runs!$A:$A, 0)), $B11) -> Industry NO2 | AI11: =IF($AG11=1, $AH11, $B11) -> transportation NO2 | AJ11: =IF($AG11=1, IF($AD11=1, Keys!$C$9, "") & IF($AE11=1, Keys!$C$10, "") & IF($AF11=1, Keys!$C$11, ""), "") | AK11: =IF($AG11=1, IFERROR(INDEX($AG$2:$AG$577, MATCH($A11 & Keys!$C$8 & $AH11, $Y$2:$Y$577, 0)), 1), 0) -> 0
A12: Alabama | B12: transportation PM25 | C12: 67 | D12: 20.189767 | E12: 0.062471315 | F12: 43.71502 | G12: 58.868077 | H12: 89.942375 | I12: 1.7622393 | J12: 10.561559 | K12: 5341.694 | L12: 902.03843 | M12: 2.2247506 | N12: 192.52547 | O12: 4.2394187 | P12: 0.14419044 | Q12: 0.56723169 | R12: 10.239586 | S12: 130.15553 | T12: 185.08865 | U12: 1666.9922 | V12: 0 | W12: 0 | Y12: =$A12 & Keys!$C$8 & $B12 -> Alabama|transportation PM25 | Z12: =IFERROR(INDEX($U12:$W12, MATCH(INDEX(Runs!$D:$D, MATCH($B12, Runs!$A:$A, 0)), $U$1:$W$1, 0)), 0) -> 1666.9922 | AA12: =IFERROR($D12/$Z12, 0) -> 0.012111495 | AB12: =IFERROR(VLOOKUP(INDEX(Runs!$F:$F, MATCH($B12, Runs!$A:$A, 0)), US_national_yearly!$D:$AM, MATCH(Keys!$C$7, US_national_yearly!$D$1:$AM$1, 0), FALSE), 0) -> 0.028248684 | AC12: =IFERROR($AA12/$AB12, 0) -> 0.42874545 | AD12: =IF($Z12<Keys!$C$3, 1, 0) -> 0 | AE12: =IF($AC12>Keys!$C$4, 1, 0) -> 0 | AF12: =IF($AC12<Keys!$C$5, 1, 0) -> 0 | AG12: =IF($AD12+$AE12+$AF12>0, 1, 0) -> 0 | AH12: =IFERROR(INDEX(Runs!$E:$E, MATCH($B12, Runs!$A:$A, 0)), $B12) -> Industry PM25 | AI12: =IF($AG12=1, $AH12, $B12) -> transportation PM25 | AJ12: =IF($AG12=1, IF($AD12=1, Keys!$C$9, "") & IF($AE12=1, Keys!$C$10, "") & IF($AF12=1, Keys!$C$11, ""), "") | AK12: =IF($AG12=1, IFERROR(INDEX($AG$2:$AG$577, MATCH($A12 & Keys!$C$8 & $AH12, $Y$2:$Y$577, 0)), 1), 0) -> 0
A13: Alabama | B13: transportation SO2 | C13: 67 | D13: 0.8477897 | E13: 0.0025950782 | F13: 1.8276556 | G13: 2.4612056 | H13: 3.7602975 | I13: 0.074074283 | J13: 0.44309781 | K13: 222.02546 | L13: 37.480784 | M13: 0.093303547 | N13: 8.0491588 | O13: 0.17665699 | P13: 0.0060240413 | Q13: 0.023680927 | R13: 0.42899161 | S13: 5.4524356 | T13: 7.751418 | U13: 0 | V13: 445.15803 | W13: 0 | Y13: =$A13 & Keys!$C$8 & $B13 -> Alabama|transportation SO2 | Z13: =IFERROR(INDEX($U13:$W13, MATCH(INDEX(Runs!$D:$D, MATCH($B13, Runs!$A:$A, 0)), $U$1:$W$1, 0)), 0) -> 445.15803 | AA13: =IFERROR($D13/$Z13, 0) -> 0.0019044691 | AB13: =IFERROR(VLOOKUP(INDEX(Runs!$F:$F, MATCH($B13, Runs!$A:$A, 0)), US_national_yearly!$D:$AM, MATCH(Keys!$C$7, US_national_yearly!$D$1:$AM$1, 0), FALSE), 0) -> 0.0051800714 | AC13: =IFERROR($AA13/$AB13, 0) -> 0.36765306 | AD13: =IF($Z13<Keys!$C$3, 1, 0) -> 0 | AE13: =IF($AC13>Keys!$C$4, 1, 0) -> 0 | AF13: =IF($AC13<Keys!$C$5, 1, 0) -> 0 | AG13: =IF($AD13+$AE13+$AF13>0, 1, 0) -> 0 | AH13: =IFERROR(INDEX(Runs!$E:$E, MATCH($B13, Runs!$A:$A, 0)), $B13) -> Industry SO2 | AI13: =IF($AG13=1, $AH13, $B13) -> transportation SO2 | AJ13: =IF($AG13=1, IF($AD13=1, Keys!$C$9, "") & IF($AE13=1, Keys!$C$10, "") & IF($AF13=1, Keys!$C$11, ""), "") | AK13: =IF($AG13=1, IFERROR(INDEX($AG$2:$AG$577, MATCH($A13 & Keys!$C$8 & $AH13, $Y$2:$Y$577, 0)), 1), 0) -> 0
... A577: Wyoming | B577: transportation SO2 | C577: 23 | D577: 0.00949479 | E577: 2.1242351e-05 | F577: 0.024856517 | G577: 0.03347295 | H577: 0.051140845 | I577: 0.00061204031 | J577: 0.0029111102 | K577: 2.8635623 | L577: 0.48624728 | M577: 0.00064200831 | N577: 0.10947031 | O577: 0.0017326118 | P577: 6.9369824e-05 | Q577: 0.00013298312 | R577: 0.0058658305 | S577: 0.074484382 | T577: 0.10572371 | U577: 0 | V577: 59.925683 | W577: 0 | Y577: =$A577 & Keys!$C$8 & $B577 -> Wyoming|transportation SO2 | Z577: =IFERROR(INDEX($U577:$W577, MATCH(INDEX(Runs!$D:$D, MATCH($B577, Runs!$A:$A, 0)), $U$1:$W$1, 0)), 0) -> 59.925683 | AA577: =IFERROR($D577/$Z577, 0) -> 0.00015844275 | AB577: =IFERROR(VLOOKUP(INDEX(Runs!$F:$F, MATCH($B577, Runs!$A:$A, 0)), US_national_yearly!$D:$AM, MATCH(Keys!$C$7, US_national_yearly!$D$1:$AM$1, 0), FALSE), 0) -> 0.0051800714 | AC577: =IFERROR($AA577/$AB577, 0) -> 0.030586982 | AD577: =IF($Z577<Keys!$C$3, 1, 0) -> 0 | AE577: =IF($AC577>Keys!$C$4, 1, 0) -> 0 | AF577: =IF($AC577<Keys!$C$5, 1, 0) -> 0 | AG577: =IF($AD577+$AE577+$AF577>0, 1, 0) -> 0 | AH577: =IFERROR(INDEX(Runs!$E:$E, MATCH($B577, Runs!$A:$A, 0)), $B577) -> Industry SO2 | AI577: =IF($AG577=1, $AH577, $B577) -> transportation SO2 | AJ577: =IF($AG577=1, IF($AD577=1, Keys!$C$9, "") & IF($AE577=1, Keys!$C$10, "") & IF($AF577=1, Keys!$C$11, ""), "") | AK577: =IF($AG577=1, IFERROR(INDEX($AG$2:$AG$577, MATCH($A577 & Keys!$C$8 & $AH577, $Y$2:$Y$577, 0)), 1), 0) -> 0

Sheet US_national_yearly
A1: sector | B1: pollutant | C1: outcome_label | D1: lookup_key | E1: 2016 | F1: 2017 | G1: 2018 | H1: 2019 | I1: 2020 | J1: 2021 | K1: 2022 | L1: 2023 | M1: 2024 | N1: 2025 | O1: 2026 | P1: 2027 | Q1: 2028 | R1: 2029 | S1: 2030 | T1: 2031 | U1: 2032 | V1: 2033 | W1: 2034 | X1: 2035 | Y1: 2036 | Z1: 2037 | AA1: 2038 | AB1: 2039 | AC1: 2040 | AD1: 2041 | AE1: 2042 | AF1: 2043 | AG1: 2044 | AH1: 2045 | AI1: 2046 | AJ1: 2047 | AK1: 2048 | AL1: 2049 | AM1: 2050
A2: transport | B2: NOx | C2: Premature mortality | D2: transport|NOx|Premature mortality | E2: 0.0053077173 | F2: 0.0053538922 | G2: 0.0054000671 | H2: 0.005446242 | I2: 0.0054924169 | J2: 0.0055385918 | K2: 0.0055847667 | L2: 0.0056309416 | M2: 0.0057148836 | N2: 0.0057988256 | O2: 0.0058827675 | P2: 0.0059667095 | Q2: 0.0060506515 | R2: 0.0062014312 | S2: 0.0063522108 | T2: 0.0064495419 | U2: 0.006546873 | V2: 0.0066442042 | W2: 0.0067415353 | X2: 0.0068388664 | Y2: 0.0069109689 | Z2: 0.0069830714 | AA2: 0.0070551739 | AB2: 0.0071272765 | AC2: 0.007199379 | AD2: 0.0072321503 | AE2: 0.0072649216 | AF2: 0.0072976929 | AG2: 0.0073304642 | AH2: 0.0073632356 | AI2: 0.0073643707 | AJ2: 0.0073655059 | AK2: 0.0073666411 | AL2: 0.0073677763 | AM2: 0.0073689115
A3: transport | B3: NOx | C3: Infant mortality | D3: transport|NOx|Infant mortality | E3: 1.0320195e-05 | F3: 1.0204687e-05 | G3: 1.0089178e-05 | H3: 9.9736694e-06 | I3: 9.8581608e-06 | J3: 9.7426522e-06 | K3: 9.6271436e-06 | L3: 9.511635e-06 | M3: 9.4218677e-06 | N3: 9.3321004e-06 | O3: 9.2423331e-06 | P3: 9.1525658e-06 | Q3: 9.0627985e-06 | R3: 6.0163332e-06 | S3: 2.9698678e-06 | T3: 2.948868e-06 | U3: 2.9278682e-06 | V3: 2.9068684e-06 | W3: 2.8858686e-06 | X3: 2.8648688e-06 | Y3: 2.85093e-06 | Z3: 2.8369913e-06 | AA3: 2.8230525e-06 | AB3: 2.8091137e-06 | AC3: 2.7951749e-06 | AD3: 2.7784182e-06 | AE3: 2.7616616e-06 | AF3: 2.744905e-06 | AG3: 2.7281483e-06 | AH3: 2.7113917e-06 | AI3: 2.6936456e-06 | AJ3: 2.6758995e-06 | AK3: 2.6581534e-06 | AL3: 2.6404073e-06 | AM3: 2.6226612e-06
A4: transport | B4: NOx | C4: Asthma symptoms albuturol use | D4: transport|NOx|Asthma symptoms albuturol use | E4: 0.52066088 | F4: 0.52207377 | G4: 0.52348665 | H4: 0.52489954 | I4: 0.52631242 | J4: 0.52772531 | K4: 0.52913819 | L4: 0.53055108 | M4: 0.53576191 | N4: 0.54097275 | O4: 0.54618359 | P4: 0.55139442 | Q4: 0.55660526 | R4: 0.56263695 | S4: 0.56866863 | T4: 0.57282421 | U4: 0.57697978 | V4: 0.58113536 | W4: 0.58529093 | X4: 0.58944651 | Y4: 0.59087899 | Z4: 0.59231148 | AA4: 0.59374397 | AB4: 0.59517645 | AC4: 0.59660894 | AD4: 0.59849026 | AE4: 0.60037159 | AF4: 0.60225291 | AG4: 0.60413423 | AH4: 0.60601556 | AI4: 0.60813523 | AJ4: 0.61025491 | AK4: 0.61237459 | AL4: 0.61449426 | AM4: 0.61661394
A5: transport | B5: NOx | C5: Asthma symptoms chest tightness | D5: transport|NOx|Asthma symptoms chest tightness | E5: 0.82781077 | F5: 0.83315162 | G5: 0.83849248 | H5: 0.84383333 | I5: 0.84917418 | J5: 0.85451503 | K5: 0.85985588 | L5: 0.86519673 | M5: 0.87718935 | N5: 0.88918196 | O5: 0.90117457 | P5: 0.91316718 | Q5: 0.9251598 | R5: 0.93473422 | S5: 0.94430865 | T5: 0.94760403 | U5: 0.95089941 | V5: 0.95419479 | W5: 0.95749017 | X5: 0.96078555 | Y5: 0.96460679 | Z5: 0.96842802 | AA5: 0.97224926 | AB5: 0.9760705 | AC5: 0.97989174 | AD5: 0.9848835 | AE5: 0.98987525 | AF5: 0.99486701 | AG5: 0.99985876 | AH5: 1.0048505 | AI5: 1.0094886 | AJ5: 1.0141266 | AK5: 1.0187647 | AL5: 1.0234027 | AM5: 1.0280408
A6: transport | B6: NOx | C6: Asthma symptoms cough | D6: transport|NOx|Asthma symptoms cough | E6: 0.9764694 | F6: 0.98276936 | G6: 0.98906933 | H6: 0.99536929 | I6: 1.0016693 | J6: 1.0079692 | K6: 1.0142692 | L6: 1.0205691 | M6: 1.0347154 | N6: 1.0488617 | O6: 1.0630079 | P6: 1.0771542 | Q6: 1.0913004 | R6: 1.1025942 | S6: 1.113888 | T6: 1.1177752 | U6: 1.1216623 | V6: 1.1255495 | W6: 1.1294367 | X6: 1.1333238 | Y6: 1.1378313 | Z6: 1.1423388 | AA6: 1.1468462 | AB6: 1.1513537 | AC6: 1.1558611 | AD6: 1.1617493 | AE6: 1.1676375 | AF6: 1.1735257 | AG6: 1.1794138 | AH6: 1.185302 | AI6: 1.190773 | AJ6: 1.1962439 | AK6: 1.2017149 | AL6: 1.2071859 | AM6: 1.2126568
A7: transport | B7: NOx | C7: Asthma symptoms shortness of breath | D7: transport|NOx|Asthma symptoms shortness of breath | E7: 0.41776091 | F7: 0.42045621 | G7: 0.42315151 | H7: 0.42584681 | I7: 0.42854211 | J7: 0.43123741 | K7: 0.43393271 | L7: 0.43662801 | M7: 0.44268018 | N7: 0.44873234 | O7: 0.4547845 | P7: 0.46083666 | Q7: 0.46688882 | R7: 0.47172063 | S7: 0.47655243 | T7: 0.47821547 | U7: 0.47987851 | V7: 0.48154155 | W7: 0.48320459 | X7: 0.48486763 | Y7: 0.48679604 | Z7: 0.48872446 | AA7: 0.49065288 | AB7: 0.49258129 | AC7: 0.49450971 | AD7: 0.49702884 | AE7: 0.49954796 | AF7: 0.50206709 | AG7: 0.50458622 | AH7: 0.50710534 | AI7: 0.50944597 | AJ7: 0.5117866 | AK7: 0.51412723 | AL7: 0.51646786 | AM7: 0.5188085
A8: transport | B8: NOx | C8: Asthma symptoms wheeze | D8: transport|NOx|Asthma symptoms wheeze | E8: 0.78261063 | F8: 0.78765986 | G8: 0.79270909 | H8: 0.79775832 | I8: 0.80280755 | J8: 0.80785678 | K8: 0.81290601 | L8: 0.81795524 | M8: 0.82929303 | N8: 0.84063082 | O8: 0.85196861 | P8: 0.8633064 | Q8: 0.8746442 | R8: 0.88369584 | S8: 0.89274748 | T8: 0.89586293 | U8: 0.89897837 | V8: 0.90209382 | W8: 0.90520926 | X8: 0.90832471 | Y8: 0.9119373 | Z8: 0.91554989 | AA8: 0.91916248 | AB8: 0.92277508 | AC8: 0.92638767 | AD8: 0.93110686 | AE8: 0.93582606 | AF8: 0.94054525 | AG8: 0.94526445 | AH8: 0.94998364 | AI8: 0.95436845 | AJ8: 0.95875326 | AK8: 0.96313807 | AL8: 0.96752288 | AM8: 0.97190769
A9: transport | B9: NOx | C9: Asthma incidence | D9: transport|NOx|Asthma incidence | E9: 0.021908661 | F9: 0.022147443 | G9: 0.022386226 | H9: 0.022625009 | I9: 0.022863792 | J9: 0.023102574 | K9: 0.023341357 | L9: 0.02358014 | M9: 0.023729671 | N9: 0.023879202 | O9: 0.024028733 | P9: 0.024178264 | Q9: 0.024327795 | R9: 0.024475337 | S9: 0.024622879 | T9: 0.024754944 | U9: 0.024887008 | V9: 0.025019073 | W9: 0.025151137 | X9: 0.025283202 | Y9: 0.025403307 | Z9: 0.025523412 | AA9: 0.025643518 | AB9: 0.025763623 | AC9: 0.025883728 | AD9: 0.025994718 | AE9: 0.026105708 | AF9: 0.026216697 | AG9: 0.026327687 | AH9: 0.026438677 | AI9: 0.026540772 | AJ9: 0.026642867 | AK9: 0.026744963 | AL9: 0.026847058 | AM9: 0.026949153
A10: transport | B10: NOx | C10: Hay fever rhinitis incidence | D10: transport|NOx|Hay fever rhinitis incidence | E10: 0.14530588 | F10: 0.14612414 | G10: 0.1469424 | H10: 0.14776067 | I10: 0.14857893 | J10: 0.14939719 | K10: 0.15021546 | L10: 0.15103372 | M10: 0.15246821 | N10: 0.1539027 | O10: 0.15533719 | P10: 0.15677168 | Q10: 0.15820617 | R10: 0.15978357 | S10: 0.16136097 | T10: 0.16257985 | U10: 0.16379873 | V10: 0.16501761 | W10: 0.1662365 | X10: 0.16745538 | Y10: 0.16810408 | Z10: 0.16875278 | AA10: 0.16940148 | AB10: 0.17005019 | AC10: 0.17069889 | AD10: 0.17143698 | AE10: 0.17217508 | AF10: 0.17291317 | AG10: 0.17365127 | AH10: 0.17438936 | AI10: 0.17515154 | AJ10: 0.17591371 | AK10: 0.17667589 | AL10: 0.17743806 | AM10: 0.17820024
A11: transport | B11: NOx | C11: Respiratory emergency room visits | D11: transport|NOx|Respiratory emergency room visits | E11: 0.0085179683 | F11: 0.0085987928 | G11: 0.0086796172 | H11: 0.0087604417 | I11: 0.0088412662 | J11: 0.0089220907 | K11: 0.0090029152 | L11: 0.0090837396 | M11: 0.0091734366 | N11: 0.0092631336 | O11: 0.0093528306 | P11: 0.0094425276 | Q11: 0.0095322246 | R11: 0.0096250304 | S11: 0.0097178362 | T11: 0.0098053651 | U11: 0.009892894 | V11: 0.0099804229 | W11: 0.010067952 | X11: 0.010155481 | Y11: 0.010229886 | Z11: 0.010304292 | AA11: 0.010378698 | AB11: 0.010453103 | AC11: 0.010527509 | AD11: 0.010591528 | AE11: 0.010655548 | AF11: 0.010719567 | AG11: 0.010783587 | AH11: 0.010847607 | AI11: 0.010907253 | AJ11: 0.010966899 | AK11: 0.011026545 | AL11: 0.011086191 | AM11: 0.011145838
A12: transport | B12: NOx | C12: Respiratory hospital admissions | D12: transport|NOx|Respiratory hospital admissions | E12: 0.00038257809 | F12: 0.00039314226 | G12: 0.00040370644 | H12: 0.00041427062 | I12: 0.0004248348 | J12: 0.00043539897 | K12: 0.00044596315 | L12: 0.00045652733 | M12: 0.00046820658 | N12: 0.00047988584 | O12: 0.0004915651 | P12: 0.00050324435 | Q12: 0.00051492361 | R12: 0.00052608938 | S12: 0.00053725514 | T12: 0.00054673511 | U12: 0.00055621507 | V12: 0.00056569504 | W12: 0.000575175 | X12: 0.00058465497 | Y12: 0.0005909925 | Z12: 0.00059733002 | AA12: 0.00060366755 | AB12: 0.00061000508 | AC12: 0.00061634261 | AD12: 0.00061973808 | AE12: 0.00062313356 | AF12: 0.00062652903 | AG12: 0.00062992451 | AH12: 0.00063331998 | AI12: 0.00063564035 | AJ12: 0.00063796072 | AK12: 0.00064028108 | AL12: 0.00064260145 | AM12: 0.00064492182
... A331: LULUCF | B331: SO2 | C331: School loss days | D331: LULUCF|SO2|School loss days | E331: 0 | F331: 0 | G331: 0 | H331: 0 | I331: 0 | J331: 0 | K331: 0 | L331: 0 | M331: 0 | N331: 0 | O331: 0 | P331: 0 | Q331: 0 | R331: 0 | S331: 0 | T331: 0 | U331: 0 | V331: 0 | W331: 0 | X331: 0 | Y331: 0 | Z331: 0 | AA331: 0 | AB331: 0 | AC331: 0 | AD331: 0 | AE331: 0 | AF331: 0 | AG331: 0 | AH331: 0 | AI331: 0 | AJ331: 0 | AK331: 0 | AL331: 0 | AM331: 0

Sheet Substitution
A1: Which COBRA run feeds each output tab for the state selected on About!B1?
A2: Column G is the answer: the run whose incidents and tons the output tab divides. It equals the tab's own run (column D) unless COBRA_aggregated flagged that run as degenerate for this state (column E = 1), in which case it is the substitute in column F. Columns H-J are comparison only. Column L must be 0 in every row.
A4: Sector workbook name | B4: Pollutant tab suffix | C4: Output tab | D4: Own COBRA run sector pollutant | E4: Flagged for this state? 1 = substituted | F4: Substitute run same state, Industry, same pollutant | G4: RUN USED IN THE OUTPUT FILE | H4: Own factor, premature deaths per ton comparison only | I4: eps-us national factor, anchor year comparison only | J4: Own factor as a multiple of national comparison only | K4: Why substituted blank = own run | L4: CHECK: is the substitute itself flagged? 1 = problem | M4: US_national_yearly key prefix for this tab sector | pollutant | (outcome label follows)
A5: transport | B5: PM25 | C5: HOIpTP-transport-PM25 | D5: transportation PM25 | E5: =IFERROR(INDEX(COBRA_aggregated!$AG:$AG, MATCH(About!$B$1 & Keys!$C$8 & $D5, COBRA_aggregated!$Y:$Y, 0)), 0) -> 0 | F5: =IFERROR(INDEX(Runs!$E:$E, MATCH($D5, Runs!$A:$A, 0)), $D5) -> Industry PM25 | G5: =IF($E5=1, $F5, $D5) -> transportation PM25 | H5: =IFERROR(INDEX(COBRA_aggregated!$AA:$AA, MATCH(About!$B$1 & Keys!$C$8 & $D5, COBRA_aggregated!$Y:$Y, 0)), 0) -> 0.05588365 | I5: =IFERROR(INDEX(COBRA_aggregated!$AB:$AB, MATCH(About!$B$1 & Keys!$C$8 & $D5, COBRA_aggregated!$Y:$Y, 0)), 0) -> 0.028248684 | J5: =IFERROR($H5/$I5, 0) -> 1.9782745 | K5: =IFERROR(INDEX(COBRA_aggregated!$AJ:$AJ, MATCH(About!$B$1 & Keys!$C$8 & $D5, COBRA_aggregated!$Y:$Y, 0)), "") | L5: =IF($E5=1, IFERROR(INDEX(COBRA_aggregated!$AG:$AG, MATCH(About!$B$1 & Keys!$C$8 & $F5, COBRA_aggregated!$Y:$Y, 0)), 0), 0) -> 0 | M5: =$A5 & Keys!$C$8 & $B5 & Keys!$C$8 -> transport|PM25|
A6: transport | B6: NOx | C6: HOIpTP-transport-NOx | D6: transportation NO2 | E6: =IFERROR(INDEX(COBRA_aggregated!$AG:$AG, MATCH(About!$B$1 & Keys!$C$8 & $D6, COBRA_aggregated!$Y:$Y, 0)), 0) -> 0 | F6: =IFERROR(INDEX(Runs!$E:$E, MATCH($D6, Runs!$A:$A, 0)), $D6) -> Industry NO2 | G6: =IF($E6=1, $F6, $D6) -> transportation NO2 | H6: =IFERROR(INDEX(COBRA_aggregated!$AA:$AA, MATCH(About!$B$1 & Keys!$C$8 & $D6, COBRA_aggregated!$Y:$Y, 0)), 0) -> 0.0018422589 | I6: =IFERROR(INDEX(COBRA_aggregated!$AB:$AB, MATCH(About!$B$1 & Keys!$C$8 & $D6, COBRA_aggregated!$Y:$Y, 0)), 0) -> 0.0057148836 | J6: =IFERROR($H6/$I6, 0) -> 0.32236157 | K6: =IFERROR(INDEX(COBRA_aggregated!$AJ:$AJ, MATCH(About!$B$1 & Keys!$C$8 & $D6, COBRA_aggregated!$Y:$Y, 0)), "") | L6: =IF($E6=1, IFERROR(INDEX(COBRA_aggregated!$AG:$AG, MATCH(About!$B$1 & Keys!$C$8 & $F6, COBRA_aggregated!$Y:$Y, 0)), 0), 0) -> 0 | M6: =$A6 & Keys!$C$8 & $B6 & Keys!$C$8 -> transport|NOx|
A7: transport | B7: SO2 | C7: HOIpTP-transport-SO2 | D7: transportation SO2 | E7: =IFERROR(INDEX(COBRA_aggregated!$AG:$AG, MATCH(About!$B$1 & Keys!$C$8 & $D7, COBRA_aggregated!$Y:$Y, 0)), 0) -> 0 | F7: =IFERROR(INDEX(Runs!$E:$E, MATCH($D7, Runs!$A:$A, 0)), $D7) -> Industry SO2 | G7: =IF($E7=1, $F7, $D7) -> transportation SO2 | H7: =IFERROR(INDEX(COBRA_aggregated!$AA:$AA, MATCH(About!$B$1 & Keys!$C$8 & $D7, COBRA_aggregated!$Y:$Y, 0)), 0) -> 0.0093831736 | I7: =IFERROR(INDEX(COBRA_aggregated!$AB:$AB, MATCH(About!$B$1 & Keys!$C$8 & $D7, COBRA_aggregated!$Y:$Y, 0)), 0) -> 0.0051800714 | J7: =IFERROR($H7/$I7, 0) -> 1.8113985 | K7: =IFERROR(INDEX(COBRA_aggregated!$AJ:$AJ, MATCH(About!$B$1 & Keys!$C$8 & $D7, COBRA_aggregated!$Y:$Y, 0)), "") | L7: =IF($E7=1, IFERROR(INDEX(COBRA_aggregated!$AG:$AG, MATCH(About!$B$1 & Keys!$C$8 & $F7, COBRA_aggregated!$Y:$Y, 0)), 0), 0) -> 0 | M7: =$A7 & Keys!$C$8 & $B7 & Keys!$C$8 -> transport|SO2|
A8: electricity | B8: PM25 | C8: HOIpTP-electricity-PM25 | D8: electricity PM25 | E8: =IFERROR(INDEX(COBRA_aggregated!$AG:$AG, MATCH(About!$B$1 & Keys!$C$8 & $D8, COBRA_aggregated!$Y:$Y, 0)), 0) -> 0 | F8: =IFERROR(INDEX(Runs!$E:$E, MATCH($D8, Runs!$A:$A, 0)), $D8) -> Industry PM25 | G8: =IF($E8=1, $F8, $D8) -> electricity PM25 | H8: =IFERROR(INDEX(COBRA_aggregated!$AA:$AA, MATCH(About!$B$1 & Keys!$C$8 & $D8, COBRA_aggregated!$Y:$Y, 0)), 0) -> 0.018578797 | I8: =IFERROR(INDEX(COBRA_aggregated!$AB:$AB, MATCH(About!$B$1 & Keys!$C$8 & $D8, COBRA_aggregated!$Y:$Y, 0)), 0) -> 0.024252978 | J8: =IFERROR($H8/$I8, 0) -> 0.76604187 | K8: =IFERROR(INDEX(COBRA_aggregated!$AJ:$AJ, MATCH(About!$B$1 & Keys!$C$8 & $D8, COBRA_aggregated!$Y:$Y, 0)), "") | L8: =IF($E8=1, IFERROR(INDEX(COBRA_aggregated!$AG:$AG, MATCH(About!$B$1 & Keys!$C$8 & $F8, COBRA_aggregated!$Y:$Y, 0)), 0), 0) -> 0 | M8: =$A8 & Keys!$C$8 & $B8 & Keys!$C$8 -> electricity|PM25|
A9: electricity | B9: NOx | C9: HOIpTP-electricity-NOx | D9: electricity NO2 | E9: =IFERROR(INDEX(COBRA_aggregated!$AG:$AG, MATCH(About!$B$1 & Keys!$C$8 & $D9, COBRA_aggregated!$Y:$Y, 0)), 0) -> 0 | F9: =IFERROR(INDEX(Runs!$E:$E, MATCH($D9, Runs!$A:$A, 0)), $D9) -> Industry NO2 | G9: =IF($E9=1, $F9, $D9) -> electricity NO2 | H9: =IFERROR(INDEX(COBRA_aggregated!$AA:$AA, MATCH(About!$B$1 & Keys!$C$8 & $D9, COBRA_aggregated!$Y:$Y, 0)), 0) -> 0.00042371712 | I9: =IFERROR(INDEX(COBRA_aggregated!$AB:$AB, MATCH(About!$B$1 & Keys!$C$8 & $D9, COBRA_aggregated!$Y:$Y, 0)), 0) -> 0.0061439222 | J9: =IFERROR($H9/$I9, 0) -> 0.068965249 | K9: =IFERROR(INDEX(COBRA_aggregated!$AJ:$AJ, MATCH(About!$B$1 & Keys!$C$8 & $D9, COBRA_aggregated!$Y:$Y, 0)), "") | L9: =IF($E9=1, IFERROR(INDEX(COBRA_aggregated!$AG:$AG, MATCH(About!$B$1 & Keys!$C$8 & $F9, COBRA_aggregated!$Y:$Y, 0)), 0), 0) -> 0 | M9: =$A9 & Keys!$C$8 & $B9 & Keys!$C$8 -> electricity|NOx|
A10: electricity | B10: SO2 | C10: HOIpTP-electricity-SO2 | D10: electricity SO2 | E10: =IFERROR(INDEX(COBRA_aggregated!$AG:$AG, MATCH(About!$B$1 & Keys!$C$8 & $D10, COBRA_aggregated!$Y:$Y, 0)), 0) -> 0 | F10: =IFERROR(INDEX(Runs!$E:$E, MATCH($D10, Runs!$A:$A, 0)), $D10) -> Industry SO2 | G10: =IF($E10=1, $F10, $D10) -> electricity SO2 | H10: =IFERROR(INDEX(COBRA_aggregated!$AA:$AA, MATCH(About!$B$1 & Keys!$C$8 & $D10, COBRA_aggregated!$Y:$Y, 0)), 0) -> 0.0035794004 | I10: =IFERROR(INDEX(COBRA_aggregated!$AB:$AB, MATCH(About!$B$1 & Keys!$C$8 & $D10, COBRA_aggregated!$Y:$Y, 0)), 0) -> 0.005703233 | J10: =IFERROR($H10/$I10, 0) -> 0.62760901 | K10: =IFERROR(INDEX(COBRA_aggregated!$AJ:$AJ, MATCH(About!$B$1 & Keys!$C$8 & $D10, COBRA_aggregated!$Y:$Y, 0)), "") | L10: =IF($E10=1, IFERROR(INDEX(COBRA_aggregated!$AG:$AG, MATCH(About!$B$1 & Keys!$C$8 & $F10, COBRA_aggregated!$Y:$Y, 0)), 0), 0) -> 0 | M10: =$A10 & Keys!$C$8 & $B10 & Keys!$C$8 -> electricity|SO2|
A11: buildings | B11: PM25 | C11: HOIpTP-buildings-PM25 | D11: buildings PM25 | E11: =IFERROR(INDEX(COBRA_aggregated!$AG:$AG, MATCH(About!$B$1 & Keys!$C$8 & $D11, COBRA_aggregated!$Y:$Y, 0)), 0) -> 0 | F11: =IFERROR(INDEX(Runs!$E:$E, MATCH($D11, Runs!$A:$A, 0)), $D11) -> Industry PM25 | G11: =IF($E11=1, $F11, $D11) -> buildings PM25 | H11: =IFERROR(INDEX(COBRA_aggregated!$AA:$AA, MATCH(About!$B$1 & Keys!$C$8 & $D11, COBRA_aggregated!$Y:$Y, 0)), 0) -> 0.052599057 | I11: =IFERROR(INDEX(COBRA_aggregated!$AB:$AB, MATCH(About!$B$1 & Keys!$C$8 & $D11, COBRA_aggregated!$Y:$Y, 0)), 0) -> 0.027627705 | J11: =IFERROR($H11/$I11, 0) -> 1.9038518 | K11: =IFERROR(INDEX(COBRA_aggregated!$AJ:$AJ, MATCH(About!$B$1 & Keys!$C$8 & $D11, COBRA_aggregated!$Y:$Y, 0)), "") | L11: =IF($E11=1, IFERROR(INDEX(COBRA_aggregated!$AG:$AG, MATCH(About!$B$1 & Keys!$C$8 & $F11, COBRA_aggregated!$Y:$Y, 0)), 0), 0) -> 0 | M11: =$A11 & Keys!$C$8 & $B11 & Keys!$C$8 -> buildings|PM25|
A12: buildings | B12: NOx | C12: HOIpTP-buildings-NOx | D12: buildings NO2 | E12: =IFERROR(INDEX(COBRA_aggregated!$AG:$AG, MATCH(About!$B$1 & Keys!$C$8 & $D12, COBRA_aggregated!$Y:$Y, 0)), 0) -> 0 | F12: =IFERROR(INDEX(Runs!$E:$E, MATCH($D12, Runs!$A:$A, 0)), $D12) -> Industry NO2 | G12: =IF($E12=1, $F12, $D12) -> buildings NO2 | H12: =IFERROR(INDEX(COBRA_aggregated!$AA:$AA, MATCH(About!$B$1 & Keys!$C$8 & $D12, COBRA_aggregated!$Y:$Y, 0)), 0) -> 0.0022199334 | I12: =IFERROR(INDEX(COBRA_aggregated!$AB:$AB, MATCH(About!$B$1 & Keys!$C$8 & $D12, COBRA_aggregated!$Y:$Y, 0)), 0) -> 0.005678474 | J12: =IFERROR($H12/$I12, 0) -> 0.39093838 | K12: =IFERROR(INDEX(COBRA_aggregated!$AJ:$AJ, MATCH(About!$B$1 & Keys!$C$8 & $D12, COBRA_aggregated!$Y:$Y, 0)), "") | L12: =IF($E12=1, IFERROR(INDEX(COBRA_aggregated!$AG:$AG, MATCH(About!$B$1 & Keys!$C$8 & $F12, COBRA_aggregated!$Y:$Y, 0)), 0), 0) -> 0 | M12: =$A12 & Keys!$C$8 & $B12 & Keys!$C$8 -> buildings|NOx|
A13: buildings | B13: SO2 | C13: HOIpTP-buildings-SO2 | D13: buildings SO2 | E13: =IFERROR(INDEX(COBRA_aggregated!$AG:$AG, MATCH(About!$B$1 & Keys!$C$8 & $D13, COBRA_aggregated!$Y:$Y, 0)), 0) -> 0 | F13: =IFERROR(INDEX(Runs!$E:$E, MATCH($D13, Runs!$A:$A, 0)), $D13) -> Industry SO2 | G13: =IF($E13=1, $F13, $D13) -> buildings SO2 | H13: =IFERROR(INDEX(COBRA_aggregated!$AA:$AA, MATCH(About!$B$1 & Keys!$C$8 & $D13, COBRA_aggregated!$Y:$Y, 0)), 0) -> 0.0067285479 | I13: =IFERROR(INDEX(COBRA_aggregated!$AB:$AB, MATCH(About!$B$1 & Keys!$C$8 & $D13, COBRA_aggregated!$Y:$Y, 0)), 0) -> 0.0051581943 | J13: =IFERROR($H13/$I13, 0) -> 1.3044386 | K13: =IFERROR(INDEX(COBRA_aggregated!$AJ:$AJ, MATCH(About!$B$1 & Keys!$C$8 & $D13, COBRA_aggregated!$Y:$Y, 0)), "") | L13: =IF($E13=1, IFERROR(INDEX(COBRA_aggregated!$AG:$AG, MATCH(About!$B$1 & Keys!$C$8 & $F13, COBRA_aggregated!$Y:$Y, 0)), 0), 0) -> 0 | M13: =$A13 & Keys!$C$8 & $B13 & Keys!$C$8 -> buildings|SO2|
A14: industry | B14: PM25 | C14: HOIpTP-industry-PM25 | D14: Industry PM25 | E14: =IFERROR(INDEX(COBRA_aggregated!$AG:$AG, MATCH(About!$B$1 & Keys!$C$8 & $D14, COBRA_aggregated!$Y:$Y, 0)), 0) -> 0 | F14: =IFERROR(INDEX(Runs!$E:$E, MATCH($D14, Runs!$A:$A, 0)), $D14) -> Industry PM25 | G14: =IF($E14=1, $F14, $D14) -> Industry PM25 | H14: =IFERROR(INDEX(COBRA_aggregated!$AA:$AA, MATCH(About!$B$1 & Keys!$C$8 & $D14, COBRA_aggregated!$Y:$Y, 0)), 0) -> 0.046396808 | I14: =IFERROR(INDEX(COBRA_aggregated!$AB:$AB, MATCH(About!$B$1 & Keys!$C$8 & $D14, COBRA_aggregated!$Y:$Y, 0)), 0) -> 0.026833192 | J14: =IFERROR($H14/$I14, 0) -> 1.7290827 | K14: =IFERROR(INDEX(COBRA_aggregated!$AJ:$AJ, MATCH(About!$B$1 & Keys!$C$8 & $D14, COBRA_aggregated!$Y:$Y, 0)), "") | L14: =IF($E14=1, IFERROR(INDEX(COBRA_aggregated!$AG:$AG, MATCH(About!$B$1 & Keys!$C$8 & $F14, COBRA_aggregated!$Y:$Y, 0)), 0), 0) -> 0 | M14: =$A14 & Keys!$C$8 & $B14 & Keys!$C$8 -> industry|PM25|
A15: industry | B15: NOx | C15: HOIpTP-industry-NOx | D15: Industry NO2 | E15: =IFERROR(INDEX(COBRA_aggregated!$AG:$AG, MATCH(About!$B$1 & Keys!$C$8 & $D15, COBRA_aggregated!$Y:$Y, 0)), 0) -> 0 | F15: =IFERROR(INDEX(Runs!$E:$E, MATCH($D15, Runs!$A:$A, 0)), $D15) -> Industry NO2 | G15: =IF($E15=1, $F15, $D15) -> Industry NO2 | H15: =IFERROR(INDEX(COBRA_aggregated!$AA:$AA, MATCH(About!$B$1 & Keys!$C$8 & $D15, COBRA_aggregated!$Y:$Y, 0)), 0) -> 0.0004362041 | I15: =IFERROR(INDEX(COBRA_aggregated!$AB:$AB, MATCH(About!$B$1 & Keys!$C$8 & $D15, COBRA_aggregated!$Y:$Y, 0)), 0) -> 0.0058012217 | J15: =IFERROR($H15/$I15, 0) -> 0.075191764 | K15: =IFERROR(INDEX(COBRA_aggregated!$AJ:$AJ, MATCH(About!$B$1 & Keys!$C$8 & $D15, COBRA_aggregated!$Y:$Y, 0)), "") | L15: =IF($E15=1, IFERROR(INDEX(COBRA_aggregated!$AG:$AG, MATCH(About!$B$1 & Keys!$C$8 & $F15, COBRA_aggregated!$Y:$Y, 0)), 0), 0) -> 0 | M15: =$A15 & Keys!$C$8 & $B15 & Keys!$C$8 -> industry|NOx|
A16: industry | B16: SO2 | C16: HOIpTP-industry-SO2 | D16: Industry SO2 | E16: =IFERROR(INDEX(COBRA_aggregated!$AG:$AG, MATCH(About!$B$1 & Keys!$C$8 & $D16, COBRA_aggregated!$Y:$Y, 0)), 0) -> 0 | F16: =IFERROR(INDEX(Runs!$E:$E, MATCH($D16, Runs!$A:$A, 0)), $D16) -> Industry SO2 | G16: =IF($E16=1, $F16, $D16) -> Industry SO2 | H16: =IFERROR(INDEX(COBRA_aggregated!$AA:$AA, MATCH(About!$B$1 & Keys!$C$8 & $D16, COBRA_aggregated!$Y:$Y, 0)), 0) -> 0.016629735 | I16: =IFERROR(INDEX(COBRA_aggregated!$AB:$AB, MATCH(About!$B$1 & Keys!$C$8 & $D16, COBRA_aggregated!$Y:$Y, 0)), 0) -> 0.0053000352 | J16: =IFERROR($H16/$I16, 0) -> 3.137665 | K16: =IFERROR(INDEX(COBRA_aggregated!$AJ:$AJ, MATCH(About!$B$1 & Keys!$C$8 & $D16, COBRA_aggregated!$Y:$Y, 0)), "") | L16: =IF($E16=1, IFERROR(INDEX(COBRA_aggregated!$AG:$AG, MATCH(About!$B$1 & Keys!$C$8 & $F16, COBRA_aggregated!$Y:$Y, 0)), 0), 0) -> 0 | M16: =$A16 & Keys!$C$8 & $B16 & Keys!$C$8 -> industry|SO2|
... A19: LULUCF | B19: SO2 | C19: HOIpTP-LULUCF-SO2 | D19: Industry NO2 | E19: =IFERROR(INDEX(COBRA_aggregated!$AG:$AG, MATCH(About!$B$1 & Keys!$C$8 & $D19, COBRA_aggregated!$Y:$Y, 0)), 0) -> 0 | F19: =IFERROR(INDEX(Runs!$E:$E, MATCH($D19, Runs!$A:$A, 0)), $D19) -> Industry NO2 | G19: =IF($E19=1, $F19, $D19) -> Industry NO2 | H19: =IFERROR(INDEX(COBRA_aggregated!$AA:$AA, MATCH(About!$B$1 & Keys!$C$8 & $D19, COBRA_aggregated!$Y:$Y, 0)), 0) -> 0.0004362041 | I19: =IFERROR(INDEX(COBRA_aggregated!$AB:$AB, MATCH(About!$B$1 & Keys!$C$8 & $D19, COBRA_aggregated!$Y:$Y, 0)), 0) -> 0.0058012217 | J19: =IFERROR($H19/$I19, 0) -> 0.075191764 | K19: =IFERROR(INDEX(COBRA_aggregated!$AJ:$AJ, MATCH(About!$B$1 & Keys!$C$8 & $D19, COBRA_aggregated!$Y:$Y, 0)), "") | L19: =IF($E19=1, IFERROR(INDEX(COBRA_aggregated!$AG:$AG, MATCH(About!$B$1 & Keys!$C$8 & $F19, COBRA_aggregated!$Y:$Y, 0)), 0), 0) -> 0 | M19: =$A19 & Keys!$C$8 & $B19 & Keys!$C$8 -> LULUCF|SO2|
A21: Tabs substituted for this state | E21: =SUM($E$5:$E$19) -> 0
A22: CHECK: substitutes that are themselves flagged (must be 0) | L22: =SUM($L$5:$L$19) -> 0
A24: All 48 states: state-run pairs substituted | E24: =SUM(COBRA_aggregated!$AG:$AG) -> 3
A25: All 48 states: CHECK substitutes themselves flagged (must be 0) | L25: =SUM(COBRA_aggregated!$AK:$AK) -> 0

Sheet HOIpTP-transport-PM25
A1: Unit: incidents / ton pollutant | B1: 2024 | C1: 2025 | D1: 2026 | E1: 2027 | F1: 2028 | G1: 2029 | H1: 2030 | I1: 2031 | J1: 2032 | K1: 2033 | L1: 2034 | M1: 2035 | N1: 2036 | O1: 2037 | P1: 2038 | Q1: 2039 | R1: 2040 | S1: 2041 | T1: 2042 | U1: 2043 | V1: 2044 | W1: 2045 | X1: 2046 | Y1: 2047 | Z1: 2048 | AA1: 2049 | AB1: 2050
A2: Premature mortality | B2: =SUMIFS(COBRA_aggregated!$D:$D, COBRA_aggregated!$A:$A, About!$B$1, COBRA_aggregated!$B:$B, Substitution!$G$5)/IFERROR(SUMIFS(COBRA_aggregated!$U:$U, COBRA_aggregated!$A:$A, About!$B$1, COBRA_aggregated!$B:$B, Substitution!$G$5), 1) -> 0.05588365 | C2: =$B2 * IFERROR(VLOOKUP(Substitution!$M$5 & $A2, US_national_yearly!$D:$AM, MATCH(C$1, US_national_yearly!$D$1:$AM$1, 0), FALSE) / VLOOKUP(Substitution!$M$5 & $A2, US_national_yearly!$D:$AM, MATCH(Keys!$C$7, US_national_yearly!$D$1:$AM$1, 0), FALSE), 1) -> 0.056576485 | D2: =$B2 * IFERROR(VLOOKUP(Substitution!$M$5 & $A2, US_national_yearly!$D:$AM, MATCH(D$1, US_national_yearly!$D$1:$AM$1, 0), FALSE) / VLOOKUP(Substitution!$M$5 & $A2, US_national_yearly!$D:$AM, MATCH(Keys!$C$7, US_national_yearly!$D$1:$AM$1, 0), FALSE), 1) -> 0.05726932 | E2: =$B2 * IFERROR(VLOOKUP(Substitution!$M$5 & $A2, US_national_yearly!$D:$AM, MATCH(E$1, US_national_yearly!$D$1:$AM$1, 0), FALSE) / VLOOKUP(Substitution!$M$5 & $A2, US_national_yearly!$D:$AM, MATCH(Keys!$C$7, US_national_yearly!$D$1:$AM$1, 0), FALSE), 1) -> 0.057962155 | F2: =$B2 * IFERROR(VLOOKUP(Substitution!$M$5 & $A2, US_national_yearly!$D:$AM, MATCH(F$1, US_national_yearly!$D$1:$AM$1, 0), FALSE) / VLOOKUP(Substitution!$M$5 & $A2, US_national_yearly!$D:$AM, MATCH(Keys!$C$7, US_national_yearly!$D$1:$AM$1, 0), FALSE), 1) -> 0.058654989 | G2: =$B2 * IFERROR(VLOOKUP(Substitution!$M$5 & $A2, US_national_yearly!$D:$AM, MATCH(G$1, US_national_yearly!$D$1:$AM$1, 0), FALSE) / VLOOKUP(Substitution!$M$5 & $A2, US_national_yearly!$D:$AM, MATCH(Keys!$C$7, US_national_yearly!$D$1:$AM$1, 0), FALSE), 1) -> 0.06000428 | H2: =$B2 * IFERROR(VLOOKUP(Substitution!$M$5 & $A2, US_national_yearly!$D:$AM, MATCH(H$1, US_national_yearly!$D$1:$AM$1, 0), FALSE) / VLOOKUP(Substitution!$M$5 & $A2, US_national_yearly!$D:$AM, MATCH(Keys!$C$7, US_national_yearly!$D$1:$AM$1, 0), FALSE), 1) -> 0.061353571 | I2: =$B2 * IFERROR(VLOOKUP(Substitution!$M$5 & $A2, US_national_yearly!$D:$AM, MATCH(I$1, US_national_yearly!$D$1:$AM$1, 0), FALSE) / VLOOKUP(Substitution!$M$5 & $A2, US_national_yearly!$D:$AM, MATCH(Keys!$C$7, US_national_yearly!$D$1:$AM$1, 0), FALSE), 1) -> 0.062239841 | J2: =$B2 * IFERROR(VLOOKUP(Substitution!$M$5 & $A2, US_national_yearly!$D:$AM, MATCH(J$1, US_national_yearly!$D$1:$AM$1, 0), FALSE) / VLOOKUP(Substitution!$M$5 & $A2, US_national_yearly!$D:$AM, MATCH(Keys!$C$7, US_national_yearly!$D$1:$AM$1, 0), FALSE), 1) -> 0.063126112 | ... AB2: =$B2 * IFERROR(VLOOKUP(Substitution!$M$5 & $A2, US_national_yearly!$D:$AM, MATCH(AB$1, US_national_yearly!$D$1:$AM$1, 0), FALSE) / VLOOKUP(Substitution!$M$5 & $A2, US_national_yearly!$D:$AM, MATCH(Keys!$C$7, US_national_yearly!$D$1:$AM$1, 0), FALSE), 1) -> 0.071367075
A3: Infant mortality | B3: =SUMIFS(COBRA_aggregated!$E:$E, COBRA_aggregated!$A:$A, About!$B$1, COBRA_aggregated!$B:$B, Substitution!$G$5)/IFERROR(SUMIFS(COBRA_aggregated!$U:$U, COBRA_aggregated!$A:$A, About!$B$1, COBRA_aggregated!$B:$B, Substitution!$G$5), 1) -> 0.00012414934 | C3: =$B3 * IFERROR(VLOOKUP(Substitution!$M$5 & $A3, US_national_yearly!$D:$AM, MATCH(C$1, US_national_yearly!$D$1:$AM$1, 0), FALSE) / VLOOKUP(Substitution!$M$5 & $A3, US_national_yearly!$D:$AM, MATCH(Keys!$C$7, US_national_yearly!$D$1:$AM$1, 0), FALSE), 1) -> 0.00012306687 | D3: =$B3 * IFERROR(VLOOKUP(Substitution!$M$5 & $A3, US_national_yearly!$D:$AM, MATCH(D$1, US_national_yearly!$D$1:$AM$1, 0), FALSE) / VLOOKUP(Substitution!$M$5 & $A3, US_national_yearly!$D:$AM, MATCH(Keys!$C$7, US_national_yearly!$D$1:$AM$1, 0), FALSE), 1) -> 0.0001219844 | E3: =$B3 * IFERROR(VLOOKUP(Substitution!$M$5 & $A3, US_national_yearly!$D:$AM, MATCH(E$1, US_national_yearly!$D$1:$AM$1, 0), FALSE) / VLOOKUP(Substitution!$M$5 & $A3, US_national_yearly!$D:$AM, MATCH(Keys!$C$7, US_national_yearly!$D$1:$AM$1, 0), FALSE), 1) -> 0.00012090194 | F3: =$B3 * IFERROR(VLOOKUP(Substitution!$M$5 & $A3, US_national_yearly!$D:$AM, MATCH(F$1, US_national_yearly!$D$1:$AM$1, 0), FALSE) / VLOOKUP(Substitution!$M$5 & $A3, US_national_yearly!$D:$AM, MATCH(Keys!$C$7, US_national_yearly!$D$1:$AM$1, 0), FALSE), 1) -> 0.00011981947 | G3: =$B3 * IFERROR(VLOOKUP(Substitution!$M$5 & $A3, US_national_yearly!$D:$AM, MATCH(G$1, US_national_yearly!$D$1:$AM$1, 0), FALSE) / VLOOKUP(Substitution!$M$5 & $A3, US_national_yearly!$D:$AM, MATCH(Keys!$C$7, US_national_yearly!$D$1:$AM$1, 0), FALSE), 1) -> 7.9686355e-05 | H3: =$B3 * IFERROR(VLOOKUP(Substitution!$M$5 & $A3, US_national_yearly!$D:$AM, MATCH(H$1, US_national_yearly!$D$1:$AM$1, 0), FALSE) / VLOOKUP(Substitution!$M$5 & $A3, US_national_yearly!$D:$AM, MATCH(Keys!$C$7, US_national_yearly!$D$1:$AM$1, 0), FALSE), 1) -> 3.9553243e-05 | I3: =$B3 * IFERROR(VLOOKUP(Substitution!$M$5 & $A3, US_national_yearly!$D:$AM, MATCH(I$1, US_national_yearly!$D$1:$AM$1, 0), FALSE) / VLOOKUP(Substitution!$M$5 & $A3, US_national_yearly!$D:$AM, MATCH(Keys!$C$7, US_national_yearly!$D$1:$AM$1, 0), FALSE), 1) -> 3.9294697e-05 | J3: =$B3 * IFERROR(VLOOKUP(Substitution!$M$5 & $A3, US_national_yearly!$D:$AM, MATCH(J$1, US_national_yearly!$D$1:$AM$1, 0), FALSE) / VLOOKUP(Substitution!$M$5 & $A3, US_national_yearly!$D:$AM, MATCH(Keys!$C$7, US_national_yearly!$D$1:$AM$1, 0), FALSE), 1) -> 3.9036151e-05 | ... AB3: =$B3 * IFERROR(VLOOKUP(Substitution!$M$5 & $A3, US_national_yearly!$D:$AM, MATCH(AB$1, US_national_yearly!$D$1:$AM$1, 0), FALSE) / VLOOKUP(Substitution!$M$5 & $A3, US_national_yearly!$D:$AM, MATCH(Keys!$C$7, US_national_yearly!$D$1:$AM$1, 0), FALSE), 1) -> 3.5345171e-05
A4: Asthma symptoms albuturol use | B4: =IFERROR(VLOOKUP(Substitution!$M$5 & $A4, US_national_yearly!$D:$AM, MATCH(Keys!$C$7, US_national_yearly!$D$1:$AM$1, 0), FALSE), 0) -> 6.1901566 | C4: =$B4 * IFERROR(VLOOKUP(Substitution!$M$5 & $A4, US_national_yearly!$D:$AM, MATCH(C$1, US_national_yearly!$D$1:$AM$1, 0), FALSE) / VLOOKUP(Substitution!$M$5 & $A4, US_national_yearly!$D:$AM, MATCH(Keys!$C$7, US_national_yearly!$D$1:$AM$1, 0), FALSE), 1) -> 6.2529806 | D4: =$B4 * IFERROR(VLOOKUP(Substitution!$M$5 & $A4, US_national_yearly!$D:$AM, MATCH(D$1, US_national_yearly!$D$1:$AM$1, 0), FALSE) / VLOOKUP(Substitution!$M$5 & $A4, US_national_yearly!$D:$AM, MATCH(Keys!$C$7, US_national_yearly!$D$1:$AM$1, 0), FALSE), 1) -> 6.3158046 | E4: =$B4 * IFERROR(VLOOKUP(Substitution!$M$5 & $A4, US_national_yearly!$D:$AM, MATCH(E$1, US_national_yearly!$D$1:$AM$1, 0), FALSE) / VLOOKUP(Substitution!$M$5 & $A4, US_national_yearly!$D:$AM, MATCH(Keys!$C$7, US_national_yearly!$D$1:$AM$1, 0), FALSE), 1) -> 6.3786286 | F4: =$B4 * IFERROR(VLOOKUP(Substitution!$M$5 & $A4, US_national_yearly!$D:$AM, MATCH(F$1, US_national_yearly!$D$1:$AM$1, 0), FALSE) / VLOOKUP(Substitution!$M$5 & $A4, US_national_yearly!$D:$AM, MATCH(Keys!$C$7, US_national_yearly!$D$1:$AM$1, 0), FALSE), 1) -> 6.4414526 | G4: =$B4 * IFERROR(VLOOKUP(Substitution!$M$5 & $A4, US_national_yearly!$D:$AM, MATCH(G$1, US_national_yearly!$D$1:$AM$1, 0), FALSE) / VLOOKUP(Substitution!$M$5 & $A4, US_national_yearly!$D:$AM, MATCH(Keys!$C$7, US_national_yearly!$D$1:$AM$1, 0), FALSE), 1) -> 6.5140601 | H4: =$B4 * IFERROR(VLOOKUP(Substitution!$M$5 & $A4, US_national_yearly!$D:$AM, MATCH(H$1, US_national_yearly!$D$1:$AM$1, 0), FALSE) / VLOOKUP(Substitution!$M$5 & $A4, US_national_yearly!$D:$AM, MATCH(Keys!$C$7, US_national_yearly!$D$1:$AM$1, 0), FALSE), 1) -> 6.5866676 | I4: =$B4 * IFERROR(VLOOKUP(Substitution!$M$5 & $A4, US_national_yearly!$D:$AM, MATCH(I$1, US_national_yearly!$D$1:$AM$1, 0), FALSE) / VLOOKUP(Substitution!$M$5 & $A4, US_national_yearly!$D:$AM, MATCH(Keys!$C$7, US_national_yearly!$D$1:$AM$1, 0), FALSE), 1) -> 6.6386343 | J4: =$B4 * IFERROR(VLOOKUP(Substitution!$M$5 & $A4, US_national_yearly!$D:$AM, MATCH(J$1, US_national_yearly!$D$1:$AM$1, 0), FALSE) / VLOOKUP(Substitution!$M$5 & $A4, US_national_yearly!$D:$AM, MATCH(Keys!$C$7, US_national_yearly!$D$1:$AM$1, 0), FALSE), 1) -> 6.6906009 | ... AB4: =$B4 * IFERROR(VLOOKUP(Substitution!$M$5 & $A4, US_national_yearly!$D:$AM, MATCH(AB$1, US_national_yearly!$D$1:$AM$1, 0), FALSE) / VLOOKUP(Substitution!$M$5 & $A4, US_national_yearly!$D:$AM, MATCH(Keys!$C$7, US_national_yearly!$D$1:$AM$1, 0), FALSE), 1) -> 7.2305038
A5: Asthma symptoms chest tightness | B5: =IFERROR(VLOOKUP(Substitution!$M$5 & $A5, US_national_yearly!$D:$AM, MATCH(Keys!$C$7, US_national_yearly!$D$1:$AM$1, 0), FALSE), 0) -> 0 | C5: =$B5 * IFERROR(VLOOKUP(Substitution!$M$5 & $A5, US_national_yearly!$D:$AM, MATCH(C$1, US_national_yearly!$D$1:$AM$1, 0), FALSE) / VLOOKUP(Substitution!$M$5 & $A5, US_national_yearly!$D:$AM, MATCH(Keys!$C$7, US_national_yearly!$D$1:$AM$1, 0), FALSE), 1) -> 0 | D5: =$B5 * IFERROR(VLOOKUP(Substitution!$M$5 & $A5, US_national_yearly!$D:$AM, MATCH(D$1, US_national_yearly!$D$1:$AM$1, 0), FALSE) / VLOOKUP(Substitution!$M$5 & $A5, US_national_yearly!$D:$AM, MATCH(Keys!$C$7, US_national_yearly!$D$1:$AM$1, 0), FALSE), 1) -> 0 | E5: =$B5 * IFERROR(VLOOKUP(Substitution!$M$5 & $A5, US_national_yearly!$D:$AM, MATCH(E$1, US_national_yearly!$D$1:$AM$1, 0), FALSE) / VLOOKUP(Substitution!$M$5 & $A5, US_national_yearly!$D:$AM, MATCH(Keys!$C$7, US_national_yearly!$D$1:$AM$1, 0), FALSE), 1) -> 0 | F5: =$B5 * IFERROR(VLOOKUP(Substitution!$M$5 & $A5, US_national_yearly!$D:$AM, MATCH(F$1, US_national_yearly!$D$1:$AM$1, 0), FALSE) / VLOOKUP(Substitution!$M$5 & $A5, US_national_yearly!$D:$AM, MATCH(Keys!$C$7, US_national_yearly!$D$1:$AM$1, 0), FALSE), 1) -> 0 | G5: =$B5 * IFERROR(VLOOKUP(Substitution!$M$5 & $A5, US_national_yearly!$D:$AM, MATCH(G$1, US_national_yearly!$D$1:$AM$1, 0), FALSE) / VLOOKUP(Substitution!$M$5 & $A5, US_national_yearly!$D:$AM, MATCH(Keys!$C$7, US_national_yearly!$D$1:$AM$1, 0), FALSE), 1) -> 0 | H5: =$B5 * IFERROR(VLOOKUP(Substitution!$M$5 & $A5, US_national_yearly!$D:$AM, MATCH(H$1, US_national_yearly!$D$1:$AM$1, 0), FALSE) / VLOOKUP(Substitution!$M$5 & $A5, US_national_yearly!$D:$AM, MATCH(Keys!$C$7, US_national_yearly!$D$1:$AM$1, 0), FALSE), 1) -> 0 | I5: =$B5 * IFERROR(VLOOKUP(Substitution!$M$5 & $A5, US_national_yearly!$D:$AM, MATCH(I$1, US_national_yearly!$D$1:$AM$1, 0), FALSE) / VLOOKUP(Substitution!$M$5 & $A5, US_national_yearly!$D:$AM, MATCH(Keys!$C$7, US_national_yearly!$D$1:$AM$1, 0), FALSE), 1) -> 0 | J5: =$B5 * IFERROR(VLOOKUP(Substitution!$M$5 & $A5, US_national_yearly!$D:$AM, MATCH(J$1, US_national_yearly!$D$1:$AM$1, 0), FALSE) / VLOOKUP(Substitution!$M$5 & $A5, US_national_yearly!$D:$AM, MATCH(Keys!$C$7, US_national_yearly!$D$1:$AM$1, 0), FALSE), 1) -> 0 | ... AB5: =$B5 * IFERROR(VLOOKUP(Substitution!$M$5 & $A5, US_national_yearly!$D:$AM, MATCH(AB$1, US_national_yearly!$D$1:$AM$1, 0), FALSE) / VLOOKUP(Substitution!$M$5 & $A5, US_national_yearly!$D:$AM, MATCH(Keys!$C$7, US_national_yearly!$D$1:$AM$1, 0), FALSE), 1) -> 0
